Workbook

Sheet count2
A1: 毕业院校 | B1: 1994 | C1: 1995 | D1: 1996 | E1: 1997 | F1: 1999 | G1: 2001 | H1: 2003 | I1: 2005 | J1: 2007 | K1: 2009 | L1: 2011 | M1: 2013 | N1: 2015 | O1: 2017 | P1: 2019 | Q1: 2021
A2: 上海交通大学 | B2: 7 | C2: 13 | D2: 1 | E2: 6 | F2: 3 | G2: 4 | H2: 2 | I2: 1 | J2: 0 | K2: 0 | L2: 2 | M2: 3 | N2: 0 | O2: 0 | P2: 2 | Q2: 0
A3: 上海光华大学 | B3: 1 | C3: 0 | D3: 0 | E3: 0 | F3: 0 | G3: 0 | H3: 0 | I3: 0 | J3: 0 | K3: 0 | L3: 0 | M3: 0 | N3: 0 | O3: 0 | P3: 0 | Q3: 0
A4: 上海华东纺织工学院 | B4: 1 | C4: 0 | D4: 0 | E4: 0 | F4: 0 | G4: 0 | H4: 0 | I4: 0 | J4: 0 | K4: 0 | L4: 0 | M4: 0 | N4: 0 | O4: 0 | P4: 0 | Q4: 0
A5: 上海圣约翰大学 | B5: 2 | C5: 0 | D5: 0 | E5: 0 | F5: 1 | G5: 0 | H5: 0 | I5: 0 | J5: 0 | K5: 0 | L5: 0 | M5: 0 | N5: 0 | O5: 0 | P5: 0 | Q5: 0
A6: 上海大同大学 | B6: 1 | C6: 1 | D6: 0 | E6: 1 | F6: 0 | G6: 1 | H6: 0 | I6: 0 | J6: 0 | K6: 0 | L6: 0 | M6: 0 | N6: 0 | O6: 0 | P6: 0 | Q6: 0
A7: 上海第一医学院 | B7: 3 | C7: 0 | D7: 0 | E7: 0 | F7: 1 | G7: 0 | H7: 2 | I7: 0 | J7: 1 | K7: 1 | L7: 0 | M7: 0 | N7: 0 | O7: 0 | P7: 0 | Q7: 0
A8: 上海震旦大学 | B8: 1 | C8: 0 | D8: 0 | E8: 0 | F8: 0 | G8: 0 | H8: 0 | I8: 0 | J8: 0 | K8: 0 | L8: 0 | M8: 0 | N8: 0 | O8: 0 | P8: 0 | Q8: 0
A9: 东北工学院 | B9: 1 | C9: 2 | D9: 0 | E9: 1 | F9: 1 | G9: 1 | H9: 2 | I9: 1 | J9: 0 | K9: 0 | L9: 0 | M9: 0 | N9: 0 | O9: 0 | P9: 0 | Q9: 0
A10: 中南矿冶学院 | B10: 1 | C10: 2 | D10: 0 | E10: 1 | F10: 0 | G10: 0 | H10: 0 | I10: 0 | J10: 0 | K10: 0 | L10: 0 | M10: 1 | N10: 0 | O10: 0 | P10: 0 | Q10: 0
A11: 中国医科大学 | B11: 2 | C11: 0 | D11: 0 | E11: 0 | F11: 2 | G11: 1 | H11: 0 | I11: 0 | J11: 0 | K11: 0 | L11: 0 | M11: 1 | N11: 0 | O11: 0 | P11: 1 | Q11: 0
A12: 中国科学技术大学 | B12: 1 | C12: 3 | D12: 0 | E12: 1 | F12: 2 | G12: 3 | H12: 1 | I12: 1 | J12: 0 | K12: 0 | L12: 1 | M12: 0 | N12: 0 | O12: 1 | P12: 0 | Q12: 0
... A456: 解放军理工大学 | B456: 0 | C456: 0 | D456: 0 | E456: 0 | F456: 0 | G456: 0 | H456: 0 | I456: 0 | J456: 0 | K456: 0 | L456: 0 | M456: 0 | N456: 0 | O456: 0 | P456: 0 | Q456: 1

Sheet Sheet1
A1: 毕业院校 | B1: 1994 | C1: 1995 | D1: 1996 | E1: 1997 | F1: 1999 | G1: 2001 | H1: 2003 | I1: 2005 | J1: 2007 | K1: 2009 | L1: 2011 | M1: 2013 | N1: 2015 | O1: 2017 | P1: 2019 | Q1: 2021
A2: 上海交通大学 | B2: 7 | C2: =B2+count2!C2 -> 20 | D2: =C2+count2!D2 -> 21 | E2: =D2+count2!E2 -> 27 | F2: =E2+count2!F2 -> 30 | G2: =F2+count2!G2 -> 34 | H2: =G2+count2!H2 -> 36 | I2: =H2+count2!I2 -> 37 | J2: =I2+count2!J2 -> 37 | ... Q2: =P2+count2!Q2 -> 44
A3: 上海光华大学 | B3: 1 | C3: =B3+count2!C3 -> 1 | D3: =C3+count2!D3 -> 1 | E3: =D3+count2!E3 -> 1 | F3: =E3+count2!F3 -> 1 | G3: =F3+count2!G3 -> 1 | H3: =G3+count2!H3 -> 1 | I3: =H3+count2!I3 -> 1 | J3: =I3+count2!J3 -> 1 | ... Q3: =P3+count2!Q3 -> 1
A4: 上海华东纺织工学院 | B4: 1 | C4: =B4+count2!C4 -> 1 | D4: =C4+count2!D4 -> 1 | E4: =D4+count2!E4 -> 1 | F4: =E4+count2!F4 -> 1 | G4: =F4+count2!G4 -> 1 | H4: =G4+count2!H4 -> 1 | I4: =H4+count2!I4 -> 1 | J4: =I4+count2!J4 -> 1 | ... Q4: =P4+count2!Q4 -> 1
A5: 上海圣约翰大学 | B5: 2 | C5: =B5+count2!C5 -> 2 | D5: =C5+count2!D5 -> 2 | E5: =D5+count2!E5 -> 2 | F5: =E5+count2!F5 -> 3 | G5: =F5+count2!G5 -> 3 | H5: =G5+count2!H5 -> 3 | I5: =H5+count2!I5 -> 3 | J5: =I5+count2!J5 -> 3 | ... Q5: =P5+count2!Q5 -> 3
A6: 上海大同大学 | B6: 1 | C6: =B6+count2!C6 -> 2 | D6: =C6+count2!D6 -> 2 | E6: =D6+count2!E6 -> 3 | F6: =E6+count2!F6 -> 3 | G6: =F6+count2!G6 -> 4 | H6: =G6+count2!H6 -> 4 | I6: =H6+count2!I6 -> 4 | J6: =I6+count2!J6 -> 4 | ... Q6: =P6+count2!Q6 -> 4
A7: 上海第一医学院 | B7: 3 | C7: =B7+count2!C7 -> 3 | D7: =C7+count2!D7 -> 3 | E7: =D7+count2!E7 -> 3 | F7: =E7+count2!F7 -> 4 | G7: =F7+count2!G7 -> 4 | H7: =G7+count2!H7 -> 6 | I7: =H7+count2!I7 -> 6 | J7: =I7+count2!J7 -> 7 | ... Q7: =P7+count2!Q7 -> 8
A8: 上海震旦大学 | B8: 1 | C8: =B8+count2!C8 -> 1 | D8: =C8+count2!D8 -> 1 | E8: =D8+count2!E8 -> 1 | F8: =E8+count2!F8 -> 1 | G8: =F8+count2!G8 -> 1 | H8: =G8+count2!H8 -> 1 | I8: =H8+count2!I8 -> 1 | J8: =I8+count2!J8 -> 1 | ... Q8: =P8+count2!Q8 -> 1
A9: 东北工学院 | B9: 1 | C9: =B9+count2!C9 -> 3 | D9: =C9+count2!D9 -> 3 | E9: =D9+count2!E9 -> 4 | F9: =E9+count2!F9 -> 5 | G9: =F9+count2!G9 -> 6 | H9: =G9+count2!H9 -> 8 | I9: =H9+count2!I9 -> 9 | J9: =I9+count2!J9 -> 9 | ... Q9: =P9+count2!Q9 -> 9
A10: 中南矿冶学院 | B10: 1 | C10: =B10+count2!C10 -> 3 | D10: =C10+count2!D10 -> 3 | E10: =D10+count2!E10 -> 4 | F10: =E10+count2!F10 -> 4 | G10: =F10+count2!G10 -> 4 | H10: =G10+count2!H10 -> 4 | I10: =H10+count2!I10 -> 4 | J10: =I10+count2!J10 -> 4 | ... Q10: =P10+count2!Q10 -> 5
A11: 中国医科大学 | B11: 2 | C11: =B11+count2!C11 -> 2 | D11: =C11+count2!D11 -> 2 | E11: =D11+count2!E11 -> 2 | F11: =E11+count2!F11 -> 4 | G11: =F11+count2!G11 -> 5 | H11: =G11+count2!H11 -> 5 | I11: =H11+count2!I11 -> 5 | J11: =I11+count2!J11 -> 5 | ... Q11: =P11+count2!Q11 -> 7
A12: 中国科学技术大学 | B12: 1 | C12: =B12+count2!C12 -> 4 | D12: =C12+count2!D12 -> 4 | E12: =D12+count2!E12 -> 5 | F12: =E12+count2!F12 -> 7 | G12: =F12+count2!G12 -> 10 | H12: =G12+count2!H12 -> 11 | I12: =H12+count2!I12 -> 12 | J12: =I12+count2!J12 -> 12 | ... Q12: =P12+count2!Q12 -> 14
A13: 中央军委技术干部学校 | B13: 1 | C13: =B13+count2!C13 -> 1 | D13: =C13+count2!D13 -> 1 | E13: =D13+count2!E13 -> 1 | F13: =E13+count2!F13 -> 1 | G13: =F13+count2!G13 -> 1 | H13: =G13+count2!H13 -> 1 | I13: =H13+count2!I13 -> 1 | J13: =I13+count2!J13 -> 1 | ... Q13: =P13+count2!Q13 -> 1
... A456: 解放军理工大学 | B456: 0 | C456: =B456+count2!C456 -> 0 | D456: =C456+count2!D456 -> 0 | E456: =D456+count2!E456 -> 0 | F456: =E456+count2!F456 -> 0 | G456: =F456+count2!G456 -> 0 | H456: =G456+count2!H456 -> 0 | I456: =H456+count2!I456 -> 0 | J456: =I456+count2!J456 -> 0 | ... Q456: =P456+count2!Q456 -> 1

Sheet Sheet2
A1: 毕业院校 | B1: 1994 | C1: 1995 | D1: 1996 | E1: 1997 | F1: 1999 | G1: 2001 | H1: 2003 | I1: 2005 | J1: 2007 | K1: 2009 | L1: 2011 | M1: 2013 | N1: 2015 | O1: 2017 | P1: 2019 | Q1: 2021
A2: （法国）巴黎南大学 | B2: 0 | C2: 0 | D2: 0 | E2: 0 | F2: 0 | G2: 0 | H2: 0 | I2: 0 | J2: 0 | K2: 1 | L2: 1 | M2: 1 | N2: 1 | O2: 1 | P2: 1 | Q2: 1
A3: 爱尔兰国立大学 | B3: 0 | C3: 0 | D3: 0 | E3: 0 | F3: 0 | G3: 0 | H3: 0 | I3: 0 | J3: 0 | K3: 3 | L3: 3 | M3: 3 | N3: 3 | O3: 3 | P3: 3 | Q3: 3
A4: 安徽大学 | B4: 0 | C4: 1 | D4: 1 | E4: 1 | F4: 1 | G4: 1 | H4: 1 | I4: 1 | J4: 1 | K4: 1 | L4: 1 | M4: 1 | N4: 1 | O4: 1 | P4: 1 | Q4: 1
A5: 安徽理工大学 | B5: 0 | C5: 0 | D5: 0 | E5: 0 | F5: 0 | G5: 0 | H5: 0 | I5: 0 | J5: 0 | K5: 1 | L5: 1 | M5: 1 | N5: 1 | O5: 1 | P5: 1 | Q5: 1
A6: 安徽师范大学 | B6: 0 | C6: 0 | D6: 0 | E6: 0 | F6: 0 | G6: 0 | H6: 0 | I6: 0 | J6: 0 | K6: 0 | L6: 1 | M6: 1 | N6: 1 | O6: 1 | P6: 1 | Q6: 1
A7: 白求恩医科大学 | B7: 0 | C7: 0 | D7: 0 | E7: 0 | F7: 0 | G7: 0 | H7: 0 | I7: 0 | J7: 0 | K7: 0 | L7: 1 | M7: 1 | N7: 1 | O7: 2 | P7: 2 | Q7: 2
A8: 百泉农业专科学校 | B8: 0 | C8: 0 | D8: 0 | E8: 0 | F8: 0 | G8: 0 | H8: 0 | I8: 0 | J8: 0 | K8: 0 | L8: 0 | M8: 0 | N8: 1 | O8: 1 | P8: 1 | Q8: 1
A9: 包头医学院 | B9: 0 | C9: 0 | D9: 0 | E9: 0 | F9: 0 | G9: 0 | H9: 0 | I9: 0 | J9: 0 | K9: 0 | L9: 0 | M9: 0 | N9: 1 | O9: 1 | P9: 1 | Q9: 1
A10: 北方交通大学 | B10: 0 | C10: 0 | D10: 0 | E10: 0 | F10: 0 | G10: 0 | H10: 0 | I10: 0 | J10: 0 | K10: 0 | L10: 0 | M10: 0 | N10: 0 | O10: 1 | P10: 1 | Q10: 1
A11: 北京大学 | B11: 8 | C11: 19 | D11: 20 | E11: 25 | F11: 27 | G11: 29 | H11: 31 | I11: 33 | J11: 33 | K11: 35 | L11: 37 | M11: 37 | N11: 39 | O11: 40 | P11: 42 | Q11: 42
A12: 北京地质学院 | B12: 0 | C12: 1 | D12: 1 | E12: 3 | F12: 3 | G12: 3 | H12: 3 | I12: 3 | J12: 3 | K12: 3 | L12: 3 | M12: 3 | N12: 3 | O12: 3 | P12: 3 | Q12: 3
... A405: 重庆交通大学 | B405: 0 | C405: 1 | D405: 1 | E405: 1 | F405: 2 | G405: 2 | H405: 2 | I405: 2 | J405: 2 | K405: 2 | L405: 2 | M405: 2 | N405: 2 | O405: 2 | P405: 2 | Q405: 2

Sheet final
B1: 继承院校 | C1: 毕业院校 | D1: 1994 | E1: 1995 | F1: 1996 | G1: 1997 | H1: 1999 | I1: 2001 | J1: 2003 | K1: 2005 | L1: 2007 | M1: 2009 | N1: 2011 | O1: 2013 | P1: 2015 | Q1: 2017 | R1: 2019 | S1: 2021
A2: 1 | B2: 清华大学 | C2: 清华大学 | D2: 15 | E2: 33 | F2: 33 | G2: 42 | H2: 55 | I2: 65 | J2: 68 | K2: 73 | L2: 75 | M2: 78 | N2: 81 | O2: 84 | P2: 90 | Q2: 93 | R2: 98 | S2: 99
A3: 2 | B3: 北京大学 | C3: 北京大学 | D3: 8 | E3: 19 | F3: 20 | G3: 25 | H3: 27 | I3: 29 | J3: 31 | K3: 34 | L3: 34 | M3: 36 | N3: 38 | O3: 38 | P3: 40 | Q3: 41 | R3: 44 | S3: 44
A4: 3 | B4: 交通大学 | C4: 北方交通大学 | D4: 0 | E4: 0 | F4: 0 | G4: 0 | H4: 0 | I4: 0 | J4: 0 | K4: 0 | L4: 0 | M4: 0 | N4: 0 | O4: 0 | P4: 0 | Q4: 1 | R4: 1 | S4: 1
A5: 3 | B5: 交通大学 | C5: 交通大学 | D5: 4 | E5: 9 | F5: 9 | G5: 11 | H5: 11 | I5: 11 | J5: 12 | K5: 12 | L5: 12 | M5: 12 | N5: 12 | O5: 12 | P5: 12 | Q5: 12 | R5: 12 | S5: 12
A6: 3 | B6: 交通大学 | C6: 上海第二医科大学 | D6: 0 | E6: 0 | F6: 0 | G6: 0 | H6: 0 | I6: 0 | J6: 0 | K6: 0 | L6: 0 | M6: 0 | N6: 0 | O6: 0 | P6: 2 | Q6: 2 | R6: 2 | S6: 3
A7: 3 | B7: 交通大学 | C7: 上海交通大学 | D7: 7 | E7: 20 | F7: 21 | G7: 27 | H7: 30 | I7: 34 | J7: 36 | K7: 37 | L7: 37 | M7: 37 | N7: 39 | O7: 42 | P7: 42 | Q7: 42 | R7: 44 | S7: 45
A8: 3 | B8: 交通大学 | C8: 唐山交通大学 | D8: 1 | E8: 2 | F8: 2 | G8: 2 | H8: 2 | I8: 2 | J8: 2 | K8: 2 | L8: 2 | M8: 2 | N8: 2 | O8: 2 | P8: 2 | Q8: 2 | R8: 2 | S8: 2
A9: 3 | B9: 交通大学 | C9: 西安交通大学 | D9: 1 | E9: 2 | F9: 2 | G9: 5 | H9: 6 | I9: 7 | J9: 8 | K9: 9 | L9: 9 | M9: 9 | N9: 9 | O9: 9 | P9: 10 | Q9: 11 | R9: 13 | S9: 13
A10: 3 | B10: 交通大学 | C10: 西南交通大学 | D10: 0 | E10: 0 | F10: 0 | G10: 0 | H10: 0 | I10: 0 | J10: 0 | K10: 0 | L10: 0 | M10: 2 | N10: 2 | O10: 2 | P10: 2 | Q10: 3 | R10: 3 | S10: 3
A11: 3 | B11: 交通大学 | C11: 上海圣约翰大学 | D11: 2 | E11: 2 | F11: 2 | G11: 2 | H11: 3 | I11: 3 | J11: 3 | K11: 3 | L11: 3 | M11: 3 | N11: 3 | O11: 3 | P11: 3 | Q11: 3 | R11: 3 | S11: 3
A12: 4 | B12: 复旦大学 | C12: 复旦大学 | D12: 1 | E12: 6 | F12: 6 | G12: 10 | H12: 12 | I12: 12 | J12: 13 | K12: 13 | L12: 14 | M12: 14 | N12: 14 | O12: 15 | P12: 15 | Q12: 15 | R12: 15 | S12: 16
A13: 4 | B13: 复旦大学 | C13: 上海第一医学院 | D13: 4 | E13: 4 | F13: 5 | G13: 6 | H13: 8 | I13: 8 | J13: 10 | K13: 10 | L13: 11 | M13: 12 | N13: 12 | O13: 12 | P13: 12 | Q13: 12 | R13: 12 | S13: 12
... A29: 15 | B29: 哈尔滨工业大学 | C29: 哈尔滨工业大学 | D29: 1 | E29: 10 | F29: 10 | G29: 12 | H29: 16 | I29: 20 | J29: 24 | K29: 25 | L29: 26 | M29: 28 | N29: 29 | O29: 29 | P29: 31 | Q29: 33 | R29: 36 | S29: 39
C30: （法国）巴黎南大学 | D30: 0 | E30: 0 | F30: 0 | G30: 0 | H30: 0 | I30: 0 | J30: 0 | K30: 0 | L30: 0 | M30: 1 | N30: 1 | O30: 1 | P30: 1 | Q30: 1 | R30: 1 | S30: 1
C31: 爱尔兰国立大学 | D31: 0 | E31: 0 | F31: 0 | G31: 0 | H31: 0 | I31: 0 | J31: 0 | K31: 0 | L31: 0 | M31: 3 | N31: 3 | O31: 3 | P31: 3 | Q31: 3 | R31: 3 | S31: 3
C32: 安徽大学 | D32: 0 | E32: 1 | F32: 1 | G32: 1 | H32: 1 | I32: 1 | J32: 1 | K32: 1 | L32: 1 | M32: 1 | N32: 1 | O32: 1 | P32: 1 | Q32: 1 | R32: 1 | S32: 1
C33: 安徽理工大学 | D33: 0 | E33: 0 | F33: 0 | G33: 0 | H33: 0 | I33: 0 | J33: 0 | K33: 0 | L33: 0 | M33: 1 | N33: 1 | O33: 1 | P33: 1 | Q33: 1 | R33: 1 | S33: 1
C34: 安徽师范大学 | D34: 0 | E34: 0 | F34: 0 | G34: 0 | H34: 0 | I34: 0 | J34: 0 | K34: 0 | L34: 0 | M34: 0 | N34: 1 | O34: 1 | P34: 1 | Q34: 1 | R34: 1 | S34: 1
C35: 白求恩医科大学 | D35: 0 | E35: 0 | F35: 0 | G35: 0 | H35: 0 | I35: 0 | J35: 0 | K35: 0 | L35: 0 | M35: 0 | N35: 1 | O35: 1 | P35: 1 | Q35: 2 | R35: 2 | S35: 2
C36: 百泉农业专科学校 | D36: 0 | E36: 0 | F36: 0 | G36: 0 | H36: 0 | I36: 0 | J36: 0 | K36: 0 | L36: 0 | M36: 0 | N36: 0 | O36: 0 | P36: 1 | Q36: 1 | R36: 1 | S36: 1
C37: 包头医学院 | D37: 0 | E37: 0 | F37: 0 | G37: 0 | H37: 0 | I37: 0 | J37: 0 | K37: 0 | L37: 0 | M37: 0 | N37: 0 | O37: 0 | P37: 1 | Q37: 1 | R37: 1 | S37: 1
C38: 北京地质学院 | D38: 0 | E38: 1 | F38: 1 | G38: 3 | H38: 3 | I38: 3 | J38: 3 | K38: 3 | L38: 3 | M38: 3 | N38: 3 | O38: 3 | P38: 3 | Q38: 3 | R38: 3 | S38: 3
C39: 北京辅仁大学 | D39: 0 | E39: 1 | F39: 1 | G39: 1 | H39: 1 | I39: 1 | J39: 1 | K39: 1 | L39: 1 | M39: 1 | N39: 1 | O39: 1 | P39: 1 | Q39: 1 | R39: 1 | S39: 1
C40: 北京钢铁工业学院 | D40: 2 | E40: 4 | F40: 4 | G40: 8 | H40: 9 | I40: 10 | J40: 10 | K40: 11 | L40: 11 | M40: 11 | N40: 11 | O40: 11 | P40: 11 | Q40: 11 | R40: 11 | S40: 11
C41: 北京钢铁学院 | D41: 0 | E41: 0 | F41: 0 | G41: 1 | H41: 1 | I41: 1 | J41: 1 | K41: 1 | L41: 1 | M41: 1 | N41: 1 | O41: 1 | P41: 1 | Q41: 1 | R41: 1 | S41: 1
... C341: 西南财经大学 | D341: 0 | E341: 0 | F341: 0 | G341: 0 | H341: 0 | I341: 0 | J341: 0 | K341: 0 | L341: 0 | M341: 0 | N341: 0 | O341: 0 | P341: 1 | Q341: 1 | R341: 1 | S341: 1
B342: 拆分 | C342: 西南联合大学 | D342: 2 | E342: 5 | F342: 5 | G342: 5 | H342: 5 | I342: 5 | J342: 5 | K342: 5 | L342: 5 | M342: 5 | N342: 5 | O342: 5 | P342: 5 | Q342: 5 | R342: 5 | S342: 5
C343: 西南农学院 | D343: 0 | E343: 2 | F343: 2 | G343: 2 | H343: 3 | I343: 3 | J343: 3 | K343: 3 | L343: 3 | M343: 3 | N343: 3 | O343: 3 | P343: 3 | Q343: 3 | R343: 3 | S343: 3
C344: 西南石油大学 | D344: 0 | E344: 0 | F344: 0 | G344: 0 | H344: 0 | I344: 0 | J344: 0 | K344: 0 | L344: 0 | M344: 1 | N344: 1 | O344: 1 | P344: 1 | Q344: 2 | R344: 2 | S344: 2
C345: 希腊克里特大学 | D345: 0 | E345: 0 | F345: 0 | G345: 0 | H345: 0 | I345: 0 | J345: 0 | K345: 0 | L345: 0 | M345: 0 | N345: 0 | O345: 1 | P345: 1 | Q345: 1 | R345: 1 | S345: 1
C346: 现日本东京农工大学 | D346: 0 | E346: 1 | F346: 1 | G346: 1 | H346: 1 | I346: 1 | J346: 1 | K346: 1 | L346: 1 | M346: 1 | N346: 1 | O346: 1 | P346: 1 | Q346: 1 | R346: 1 | S346: 1
C347: 香港大学 | D347: 0 | E347: 0 | F347: 0 | G347: 0 | H347: 0 | I347: 0 | J347: 0 | K347: 1 | L347: 2 | M347: 2 | N347: 2 | O347: 2 | P347: 2 | Q347: 2 | R347: 2 | S347: 2
C348: 新风加工厂职工业余大学 | D348: 0 | E348: 0 | F348: 0 | G348: 0 | H348: 1 | I348: 1 | J348: 1 | K348: 1 | L348: 1 | M348: 1 | N348: 1 | O348: 1 | P348: 1 | Q348: 1 | R348: 1 | S348: 1
C349: 新疆兵团奎屯农校 | D349: 0 | E349: 0 | F349: 0 | G349: 0 | H349: 0 | I349: 0 | J349: 0 | K349: 0 | L349: 0 | M349: 0 | N349: 0 | O349: 1 | P349: 1 | Q349: 1 | R349: 1 | S349: 1
C350: 新疆大学 | D350: 0 | E350: 0 | F350: 0 | G350: 0 | H350: 0 | I350: 0 | J350: 0 | K350: 0 | L350: 0 | M350: 0 | N350: 1 | O350: 1 | P350: 1 | Q350: 1 | R350: 1 | S350: 1
C351: 新西兰奥塔哥大学 | D351: 0 | E351: 0 | F351: 0 | G351: 0 | H351: 0 | I351: 0 | J351: 0 | K351: 0 | L351: 0 | M351: 0 | N351: 0 | O351: 1 | P351: 1 | Q351: 1 | R351: 1 | S351: 1
C352: 新西兰梅西大学 | D352: 0 | E352: 0 | F352: 0 | G352: 0 | H352: 0 | I352: 0 | J352: 0 | K352: 0 | L352: 0 | M352: 1 | N352: 1 | O352: 1 | P352: 1 | Q352: 1 | R352: 1 | S352: 1
B353: 拆分 | C353: 燕京大学 | D353: 2 | E353: 3 | F353: 3 | G353: 3 | H353: 3 | I353: 3 | J353: 3 | K353: 3 | L353: 3 | M353: 3 | N353: 3 | O353: 3 | P353: 3 | Q353: 3 | R353: 3 | S353: 3
C354: 燕山大学 | D354: 0 | E354: 0 | F354: 0 | G354: 0 | H354: 0 | I354: 0 | J354: 0 | K354: 0 | L354: 0 | M354: 0 | N354: 0 | O354: 0 | P354: 0 | Q354: 1 | R354: 1 | S354: 1
...
