Workbook

Sheet 出生地信息处理
A1: 姓名 | B1: 出生地 | C1: 当选年份 | D1: 省 | E1: 市
A2: 陈鲸 | B2: 安徽省安庆市怀宁县 | C2: 2005 | D2: 安徽省 | E2: 安庆市
A3: 宁津生 | B3: 安徽省桐城县 | C3: 1995 | D3: 安徽省 | E3: 安庆市
A4: 冯夏庭 | B4: 安徽省潜山县 | C4: 2019 | D4: 安徽省 | E4: 安庆市
A5: 周志鑫 | B5: 安徽太湖县 | C5: 2015 | D5: 安徽省 | E5: 安庆市
A6: 汤中立 | B6: 安徽省安庆市 | C6: 1995 | D6: 安徽省 | E6: 安庆市
A7: 徐南平 | B7: 安徽省桐城市 | C7: 2005 | D7: 安徽省 | E7: 安庆市
A8: 吴曼青 | B8: 安徽省桐城市 | C8: 2009 | D8: 安徽省 | E8: 安庆市
A9: 杨善林 | B9: 安徽省怀宁县 | C9: 2013 | D9: 安徽省 | E9: 安庆市
A10: 彭寿 | B10: 安徽省桐城市 | C10: 2019 | D10: 安徽省 | E10: 安庆市
A11: 蒋昌俊 | B11: 安徽省安庆市 | C11: 2021 | D11: 安徽省 | E11: 安庆市
A12: 孙德和 | B12: 安徽桐城 | C12: 1955 | D12: 安徽省 | E12: 安庆市
A13: 杨石先 | B13: 安徽怀宁 | C13: 1955 | D13: 安徽省 | E13: 安庆市
... A1799: 顾玉东 | B1799: 山东省章丘县 | C1799: 1994 | D1799: 山东省 | E1799: 济南市
A1800: 马世骏 | C1800: 1980 | D1800: 山东省 | E1800: 济宁市
A1801: 郝吉明 | B1801: 山东省梁山县 | C1801: 2005 | D1801: 山东省 | E1801: 济宁市
A1802: 殷宏章 | B1802: 山东兖州 | C1802: 1948 | D1802: 山东省 | E1802: 济宁市
A1803: 张致一 | B1803: 山东泗水 | C1803: 1980 | D1803: 山东省 | E1803: 济宁市
A1804: 佟振合 | B1804: 山东梁山 | C1804: 1999 | D1804: 山东省 | E1804: 济宁市
A1805: 王涛 | B1805: 山东省胶县 | C1805: 1994 | D1805: 山东省 | E1805: 胶州市
A1806: 郭旭升 | B1806: 山东省茌平市 | C1806: 2019 | D1806: 山东省 | E1806: 聊城市
A1807: 王子才 | B1807: 山东省聊城市 | C1807: 2001 | D1807: 山东省 | E1807: 聊城市
A1808: 张运 | B1808: 山东省聊城市 | C1808: 2001 | D1808: 山东省 | E1808: 聊城市
A1809: 张新时 | B1809: 山东高唐 | C1809: 1991 | D1809: 山东省 | E1809: 聊城市
A1810: 王鸿祯 | B1810: 山东苍山 | C1810: 1980 | D1810: 山东省 | E1810: 临沂市
A1811: 薛群基 | B1811: 山东省沂南县 | C1811: 1997 | D1811: 山东省 | E1811: 临沂市
A1812: 邱志明 | B1812: 山东临沂 | C1812: 2015 | D1812: 山东省 | E1812: 临沂市
... A1931: 李静海 | B1931: 山西静乐 | C1931: 1999 | D1931: 山西省 | E1931: 忻州市
A1932: 张沛霖 | C1932: 1980 | D1932: 山西省 | E1932: 阳泉市
A1933: 席泽宗 | B1933: 山西垣曲 | C1933: 1991 | D1933: 山西省 | E1933: 运城市
A1934: 汪忠镐 | B1934: 主要从事动脉造影及内皮细胞种植 | C1934: 2005 | D1934: 山西省 | E1934: 运城市
A1935: 刘尚合 | B1935: 山西省闻喜市 | C1935: 1999 | D1935: 山西省 | E1935: 运城市
A1936: 徐建国 | B1936: 山西省平陆县 | C1936: 2011 | D1936: 山西省 | E1936: 运城市
A1937: 宁滨 | B1937: 山西省运城市 | C1937: 2017 | D1937: 山西省 | E1937: 运城市
A1938: 毛景文 | B1938: 山西省运城市 | C1938: 2017 | D1938: 山西省 | E1938: 运城市
A1939: 潘永信 | B1939: 山西运城 | C1939: 2017 | D1939: 山西省 | E1939: 运城市
A1940: 彭平安 | B1940: 有机地球化学家，长期从事地质体有机质地球化学研究。1960年11月15日出生。1982年毕业于浙江大学，1991年在中国科学院地球化学研究所获博士学位。2013年当选为中国科学院院士。 | C1940: 2013 | D1940: 山西省 | E1940: 长治市
A1941: 牛憨笨 | B1941: 山西省壶关县 | C1941: 1997 | D1941: 山西省 | E1941: 长治市
A1942: 张涛 | B1942: 陕西安康 | C1942: 2013 | D1942: 陕西省 | E1942: 安康市
A1943: 张福锁 | B1943: 陕西省凤翔县 | C1943: 2017 | D1943: 陕西省 | E1943: 宝鸡市
...

Sheet 省
B1: 省 | C1: 1948 | D1: 1955 | E1: 1956 | F1: 1957 | G1: 1980 | H1: 1983 | I1: 1984 | J1: 1985 | K1: 1986 | L1: 1988 | M1: 1989 | N1: 1990 | O1: 1991 | P1: 1992 | Q1: 1993 | R1: 1994 | S1: 1995 | T1: 1996 | U1: 1997 | V1: 1999 | W1: 2001 | X1: 2003 | Y1: 2004 | Z1: 2005 | AA1: 2007 | AB1: 2009 | AC1: 2011 | AD1: 2013 | AE1: 2015 | AF1: 2017 | AG1: 2019 | AH1: 2021
A2: 0 | B2: 安徽省 | C2: 0 | D2: 5 | E2: 0 | F2: 0 | G2: 12 | H2: 0 | I2: 0 | J2: 0 | K2: 0 | L2: 0 | M2: 0 | N2: 0 | O2: 5 | P2: 0 | Q2: 0 | R2: 3 | S2: 5 | T2: 2 | U2: 3 | V2: 3 | W2: 2 | X2: 4 | Y2: 0 | Z2: 6 | AA2: 3 | AB2: 4 | AC2: 4 | AD2: 10 | AE2: 10 | AF2: 10 | AG2: 12 | AH2: 7
A3: 1 | B3: 北京市 | C3: 1 | D3: 2 | E3: 0 | F3: 2 | G3: 20 | H3: 0 | I3: 0 | J3: 0 | K3: 0 | L3: 0 | M3: 0 | N3: 0 | O3: 13 | P3: 0 | Q3: 4 | R3: 12 | S3: 9 | T3: 0 | U3: 9 | V3: 5 | W3: 6 | X3: 6 | Y3: 0 | Z3: 2 | AA3: 6 | AB3: 3 | AC3: 3 | AD3: 4 | AE3: 3 | AF3: 4 | AG3: 4 | AH3: 3
A4: 2 | B4: 朝鲜 | C4: 0 | D4: 0 | E4: 0 | F4: 0 | G4: 0 | H4: 0 | I4: 0 | J4: 0 | K4: 0 | L4: 0 | M4: 0 | N4: 0 | O4: 0 | P4: 0 | Q4: 0 | R4: 0 | S4: 0 | T4: 0 | U4: 0 | V4: 0 | W4: 0 | X4: 0 | Y4: 0 | Z4: 0 | AA4: 1 | AB4: 0 | AC4: 0 | AD4: 0 | AE4: 0 | AF4: 0 | AG4: 0 | AH4: 0
A5: 3 | B5: 东帝汶 | C5: 0 | D5: 1 | E5: 0 | F5: 0 | G5: 0 | H5: 0 | I5: 0 | J5: 0 | K5: 0 | L5: 0 | M5: 0 | N5: 0 | O5: 0 | P5: 0 | Q5: 0 | R5: 0 | S5: 0 | T5: 0 | U5: 0 | V5: 0 | W5: 0 | X5: 0 | Y5: 0 | Z5: 0 | AA5: 0 | AB5: 0 | AC5: 0 | AD5: 0 | AE5: 0 | AF5: 0 | AG5: 0 | AH5: 0
A6: 4 | B6: 菲律宾 | C6: 0 | D6: 1 | E6: 0 | F6: 0 | G6: 0 | H6: 0 | I6: 0 | J6: 0 | K6: 0 | L6: 0 | M6: 0 | N6: 0 | O6: 0 | P6: 0 | Q6: 0 | R6: 0 | S6: 0 | T6: 0 | U6: 0 | V6: 0 | W6: 0 | X6: 0 | Y6: 0 | Z6: 0 | AA6: 0 | AB6: 0 | AC6: 0 | AD6: 0 | AE6: 0 | AF6: 0 | AG6: 0 | AH6: 0
A7: 5 | B7: 福建省 | C7: 3 | D7: 4 | E7: 0 | F7: 3 | G7: 17 | H7: 0 | I7: 0 | J7: 2 | K7: 0 | L7: 0 | M7: 0 | N7: 0 | O7: 13 | P7: 0 | Q7: 4 | R7: 3 | S7: 10 | T7: 1 | U7: 10 | V7: 6 | W7: 8 | X7: 8 | Y7: 0 | Z7: 6 | AA7: 1 | AB7: 2 | AC7: 1 | AD7: 3 | AE7: 0 | AF7: 2 | AG7: 2 | AH7: 4
A8: 6 | B8: 甘肃省 | C8: 0 | D8: 0 | E8: 0 | F8: 0 | G8: 0 | H8: 0 | I8: 0 | J8: 0 | K8: 0 | L8: 0 | M8: 0 | N8: 0 | O8: 0 | P8: 0 | Q8: 0 | R8: 1 | S8: 2 | T8: 0 | U8: 0 | V8: 2 | W8: 0 | X8: 7 | Y8: 0 | Z8: 0 | AA8: 2 | AB8: 2 | AC8: 1 | AD8: 0 | AE8: 1 | AF8: 2 | AG8: 3 | AH8: 2
A9: 7 | B9: 广东省 | C9: 2 | D9: 6 | E9: 0 | F9: 0 | G9: 14 | H9: 0 | I9: 0 | J9: 0 | K9: 0 | L9: 1 | M9: 0 | N9: 0 | O9: 11 | P9: 0 | Q9: 4 | R9: 9 | S9: 15 | T9: 1 | U9: 6 | V9: 13 | W9: 8 | X9: 6 | Y9: 0 | Z9: 3 | AA9: 1 | AB9: 7 | AC9: 2 | AD9: 4 | AE9: 2 | AF9: 2 | AG9: 2 | AH9: 0
A10: 8 | B10: 广西壮族自治区 | C10: 0 | D10: 0 | E10: 0 | F10: 0 | G10: 0 | H10: 0 | I10: 0 | J10: 0 | K10: 0 | L10: 0 | M10: 0 | N10: 0 | O10: 2 | P10: 0 | Q10: 0 | R10: 2 | S10: 1 | T10: 0 | U10: 3 | V10: 0 | W10: 2 | X10: 1 | Y10: 0 | Z10: 1 | AA10: 1 | AB10: 1 | AC10: 0 | AD10: 0 | AE10: 0 | AF10: 0 | AG10: 1 | AH10: 1
A11: 9 | B11: 贵州省 | C11: 0 | D11: 1 | E11: 0 | F11: 0 | G11: 1 | H11: 0 | I11: 0 | J11: 0 | K11: 0 | L11: 0 | M11: 0 | N11: 0 | O11: 1 | P11: 0 | Q11: 0 | R11: 1 | S11: 2 | T11: 0 | U11: 0 | V11: 0 | W11: 0 | X11: 0 | Y11: 0 | Z11: 0 | AA11: 0 | AB11: 2 | AC11: 3 | AD11: 0 | AE11: 0 | AF11: 0 | AG11: 0 | AH11: 2
A12: 10 | B12: 海南省 | C12: 0 | D12: 0 | E12: 0 | F12: 0 | G12: 0 | H12: 0 | I12: 0 | J12: 0 | K12: 0 | L12: 0 | M12: 0 | N12: 0 | O12: 0 | P12: 0 | Q12: 0 | R12: 0 | S12: 1 | T12: 0 | U12: 1 | V12: 0 | W12: 0 | X12: 0 | Y12: 0 | Z12: 0 | AA12: 0 | AB12: 2 | AC12: 0 | AD12: 2 | AE12: 0 | AF12: 0 | AG12: 0 | AH12: 0
A13: 11 | B13: 河北省 | C13: 0 | D13: 13 | E13: 0 | F13: 2 | G13: 10 | H13: 0 | I13: 0 | J13: 0 | K13: 0 | L13: 0 | M13: 0 | N13: 0 | O13: 4 | P13: 0 | Q13: 2 | R13: 5 | S13: 8 | T13: 0 | U13: 7 | V13: 10 | W13: 4 | X13: 3 | Y13: 0 | Z13: 0 | AA13: 2 | AB13: 5 | AC13: 3 | AD13: 4 | AE13: 3 | AF13: 10 | AG13: 6 | AH13: 6
... A42: 40 | B42: 重庆市 | C42: 0 | D42: 3 | E42: 0 | F42: 1 | G42: 2 | H42: 0 | I42: 0 | J42: 0 | K42: 0 | L42: 0 | M42: 0 | N42: 0 | O42: 0 | P42: 0 | Q42: 0 | R42: 0 | S42: 3 | T42: 0 | U42: 3 | V42: 2 | W42: 1 | X42: 2 | Y42: 0 | Z42: 2 | AA42: 0 | AB42: 1 | AC42: 2 | AD42: 4 | AE42: 4 | AF42: 1 | AG42: 1 | AH42: 2
C43: =SUM(C2:C42) -> 37 | D43: =SUM(D2:D42) -> 126 | E43: =SUM(E2:E42) -> 1 | F43: =SUM(F2:F42) -> 17 | G43: =SUM(G2:G42) -> 274 | H43: =SUM(H2:H42) -> 1 | I43: =SUM(I2:I42) -> 1 | J43: =SUM(J2:J42) -> 4 | ... AH43: =SUM(AH2:AH42) -> 146

Sheet 省累计
B1: 省 | C1: 1948 | D1: 1955 | E1: 1956 | F1: 1957 | G1: 1980 | H1: 1983 | I1: 1984 | J1: 1985 | K1: 1986 | L1: 1988 | M1: 1989 | N1: 1990 | O1: 1991 | P1: 1992 | Q1: 1993 | R1: 1994 | S1: 1995 | T1: 1996 | U1: 1997 | V1: 1999 | W1: 2001 | X1: 2003 | Y1: 2004 | Z1: 2005 | AA1: 2007 | AB1: 2009 | AC1: 2011 | AD1: 2013 | AE1: 2015 | AF1: 2017 | AG1: 2019 | AH1: 2021
A2: 0 | B2: 安徽省 | C2: 0 | D2: =C2+省!D2 -> 5 | E2: =D2+省!E2 -> 5 | F2: =E2+省!F2 -> 5 | G2: =F2+省!G2 -> 17 | H2: =G2+省!H2 -> 17 | I2: =H2+省!I2 -> 17 | J2: =I2+省!J2 -> 17 | K2: =J2+省!K2 -> 17 | ... AH2: =AG2+省!AH2 -> 110
A3: 1 | B3: 北京市 | C3: 1 | D3: =C3+省!D3 -> 3 | E3: =D3+省!E3 -> 3 | F3: =E3+省!F3 -> 5 | G3: =F3+省!G3 -> 25 | H3: =G3+省!H3 -> 25 | I3: =H3+省!I3 -> 25 | J3: =I3+省!J3 -> 25 | K3: =J3+省!K3 -> 25 | ... AH3: =AG3+省!AH3 -> 121
A4: 2 | B4: 朝鲜 | C4: 0 | D4: =C4+省!D4 -> 0 | E4: =D4+省!E4 -> 0 | F4: =E4+省!F4 -> 0 | G4: =F4+省!G4 -> 0 | H4: =G4+省!H4 -> 0 | I4: =H4+省!I4 -> 0 | J4: =I4+省!J4 -> 0 | K4: =J4+省!K4 -> 0 | ... AH4: =AG4+省!AH4 -> 1
A5: 3 | B5: 东帝汶 | C5: 0 | D5: =C5+省!D5 -> 1 | E5: =D5+省!E5 -> 1 | F5: =E5+省!F5 -> 1 | G5: =F5+省!G5 -> 1 | H5: =G5+省!H5 -> 1 | I5: =H5+省!I5 -> 1 | J5: =I5+省!J5 -> 1 | K5: =J5+省!K5 -> 1 | ... AH5: =AG5+省!AH5 -> 1
A6: 4 | B6: 菲律宾 | C6: 0 | D6: =C6+省!D6 -> 1 | E6: =D6+省!E6 -> 1 | F6: =E6+省!F6 -> 1 | G6: =F6+省!G6 -> 1 | H6: =G6+省!H6 -> 1 | I6: =H6+省!I6 -> 1 | J6: =I6+省!J6 -> 1 | K6: =J6+省!K6 -> 1 | ... AH6: =AG6+省!AH6 -> 1
A7: 5 | B7: 福建省 | C7: 3 | D7: =C7+省!D7 -> 7 | E7: =D7+省!E7 -> 7 | F7: =E7+省!F7 -> 10 | G7: =F7+省!G7 -> 27 | H7: =G7+省!H7 -> 27 | I7: =H7+省!I7 -> 27 | J7: =I7+省!J7 -> 29 | K7: =J7+省!K7 -> 29 | ... AH7: =AG7+省!AH7 -> 113
A8: 6 | B8: 甘肃省 | C8: 0 | D8: =C8+省!D8 -> 0 | E8: =D8+省!E8 -> 0 | F8: =E8+省!F8 -> 0 | G8: =F8+省!G8 -> 0 | H8: =G8+省!H8 -> 0 | I8: =H8+省!I8 -> 0 | J8: =I8+省!J8 -> 0 | K8: =J8+省!K8 -> 0 | ... AH8: =AG8+省!AH8 -> 25
A9: 7 | B9: 广东省 | C9: 2 | D9: =C9+省!D9 -> 8 | E9: =D9+省!E9 -> 8 | F9: =E9+省!F9 -> 8 | G9: =F9+省!G9 -> 22 | H9: =G9+省!H9 -> 22 | I9: =H9+省!I9 -> 22 | J9: =I9+省!J9 -> 22 | K9: =J9+省!K9 -> 22 | ... AH9: =AG9+省!AH9 -> 119
A10: 8 | B10: 广西壮族自治区 | C10: 0 | D10: =C10+省!D10 -> 0 | E10: =D10+省!E10 -> 0 | F10: =E10+省!F10 -> 0 | G10: =F10+省!G10 -> 0 | H10: =G10+省!H10 -> 0 | I10: =H10+省!I10 -> 0 | J10: =I10+省!J10 -> 0 | K10: =J10+省!K10 -> 0 | ... AH10: =AG10+省!AH10 -> 16
A11: 9 | B11: 贵州省 | C11: 0 | D11: =C11+省!D11 -> 1 | E11: =D11+省!E11 -> 1 | F11: =E11+省!F11 -> 1 | G11: =F11+省!G11 -> 2 | H11: =G11+省!H11 -> 2 | I11: =H11+省!I11 -> 2 | J11: =I11+省!J11 -> 2 | K11: =J11+省!K11 -> 2 | ... AH11: =AG11+省!AH11 -> 13
A12: 10 | B12: 海南省 | C12: 0 | D12: =C12+省!D12 -> 0 | E12: =D12+省!E12 -> 0 | F12: =E12+省!F12 -> 0 | G12: =F12+省!G12 -> 0 | H12: =G12+省!H12 -> 0 | I12: =H12+省!I12 -> 0 | J12: =I12+省!J12 -> 0 | K12: =J12+省!K12 -> 0 | ... AH12: =AG12+省!AH12 -> 6
A13: 11 | B13: 河北省 | C13: 0 | D13: =C13+省!D13 -> 13 | E13: =D13+省!E13 -> 13 | F13: =E13+省!F13 -> 15 | G13: =F13+省!G13 -> 25 | H13: =G13+省!H13 -> 25 | I13: =H13+省!I13 -> 25 | J13: =I13+省!J13 -> 25 | K13: =J13+省!K13 -> 25 | ... AH13: =AG13+省!AH13 -> 107
... A42: 40 | B42: 重庆市 | C42: 0 | D42: =C42+省!D42 -> 3 | E42: =D42+省!E42 -> 3 | F42: =E42+省!F42 -> 4 | G42: =F42+省!G42 -> 6 | H42: =G42+省!H42 -> 6 | I42: =H42+省!I42 -> 6 | J42: =I42+省!J42 -> 6 | K42: =J42+省!K42 -> 6 | ... AH42: =AG42+省!AH42 -> 34

Sheet 地级市
B1: 省 | C1: 市 | D1: 1948 | E1: 1955 | F1: 1956 | G1: 1957 | H1: 1980 | I1: 1983 | J1: 1984 | K1: 1985 | L1: 1986 | M1: 1988 | N1: 1989 | O1: 1990 | P1: 1991 | Q1: 1992 | R1: 1993 | S1: 1994 | T1: 1995 | U1: 1996 | V1: 1997 | W1: 1999 | X1: 2001 | Y1: 2003 | Z1: 2004 | AA1: 2005 | AB1: 2007 | AC1: 2009 | AD1: 2011 | AE1: 2013 | AF1: 2015 | AG1: 2017 | AH1: 2019 | AI1: 2021
A2: 0 | B2: 安徽省 | C2: 安庆市 | D2: 0 | E2: 2 | F2: 0 | G2: 0 | H2: 3 | I2: 0 | J2: 0 | K2: 0 | L2: 0 | M2: 0 | N2: 0 | O2: 0 | P2: 1 | Q2: 0 | R2: 0 | S2: 0 | T2: 2 | U2: 0 | V2: 0 | W2: 0 | X2: 0 | Y2: 1 | Z2: 0 | AA2: 3 | AB2: 0 | AC2: 1 | AD2: 1 | AE2: 3 | AF2: 1 | AG2: 3 | AH2: 5 | AI2: 1
A3: 1 | B3: 安徽省 | C3: 蚌埠市 | D3: 0 | E3: 0 | F3: 0 | G3: 0 | H3: 0 | I3: 0 | J3: 0 | K3: 0 | L3: 0 | M3: 0 | N3: 0 | O3: 0 | P3: 0 | Q3: 0 | R3: 0 | S3: 0 | T3: 0 | U3: 0 | V3: 0 | W3: 1 | X3: 0 | Y3: 0 | Z3: 0 | AA3: 0 | AB3: 0 | AC3: 0 | AD3: 1 | AE3: 1 | AF3: 0 | AG3: 0 | AH3: 0 | AI3: 0
A4: 2 | B4: 安徽省 | C4: 亳州市 | D4: 0 | E4: 0 | F4: 0 | G4: 0 | H4: 0 | I4: 0 | J4: 0 | K4: 0 | L4: 0 | M4: 0 | N4: 0 | O4: 0 | P4: 0 | Q4: 0 | R4: 0 | S4: 0 | T4: 0 | U4: 0 | V4: 0 | W4: 0 | X4: 0 | Y4: 0 | Z4: 0 | AA4: 2 | AB4: 1 | AC4: 0 | AD4: 0 | AE4: 0 | AF4: 0 | AG4: 0 | AH4: 0 | AI4: 0
A5: 3 | B5: 安徽省 | C5: 池州市 | D5: 0 | E5: 0 | F5: 0 | G5: 0 | H5: 0 | I5: 0 | J5: 0 | K5: 0 | L5: 0 | M5: 0 | N5: 0 | O5: 0 | P5: 0 | Q5: 0 | R5: 0 | S5: 0 | T5: 0 | U5: 0 | V5: 0 | W5: 0 | X5: 0 | Y5: 0 | Z5: 0 | AA5: 0 | AB5: 0 | AC5: 0 | AD5: 0 | AE5: 0 | AF5: 1 | AG5: 0 | AH5: 0 | AI5: 0
A6: 4 | B6: 安徽省 | C6: 滁州市 | D6: 0 | E6: 0 | F6: 0 | G6: 0 | H6: 2 | I6: 0 | J6: 0 | K6: 0 | L6: 0 | M6: 0 | N6: 0 | O6: 0 | P6: 0 | Q6: 0 | R6: 0 | S6: 1 | T6: 0 | U6: 0 | V6: 1 | W6: 0 | X6: 0 | Y6: 0 | Z6: 0 | AA6: 0 | AB6: 1 | AC6: 1 | AD6: 1 | AE6: 1 | AF6: 1 | AG6: 1 | AH6: 0 | AI6: 0
A7: 5 | B7: 安徽省 | C7: 阜阳市 | D7: 0 | E7: 0 | F7: 0 | G7: 0 | H7: 0 | I7: 0 | J7: 0 | K7: 0 | L7: 0 | M7: 0 | N7: 0 | O7: 0 | P7: 0 | Q7: 0 | R7: 0 | S7: 0 | T7: 0 | U7: 2 | V7: 1 | W7: 0 | X7: 0 | Y7: 1 | Z7: 0 | AA7: 0 | AB7: 0 | AC7: 0 | AD7: 0 | AE7: 2 | AF7: 1 | AG7: 0 | AH7: 0 | AI7: 0
A8: 6 | B8: 安徽省 | C8: 阜阳市 | D8: 0 | E8: 0 | F8: 0 | G8: 0 | H8: 0 | I8: 0 | J8: 0 | K8: 0 | L8: 0 | M8: 0 | N8: 0 | O8: 0 | P8: 0 | Q8: 0 | R8: 0 | S8: 0 | T8: 0 | U8: 2 | V8: 1 | W8: 0 | X8: 0 | Y8: 1 | Z8: 0 | AA8: 0 | AB8: 0 | AC8: 0 | AD8: 0 | AE8: 2 | AF8: 1 | AG8: 0 | AH8: 0 | AI8: 0
A9: 7 | B9: 安徽省 | C9: 合肥市 | D9: 0 | E9: 0 | F9: 0 | G9: 0 | H9: 2 | I9: 0 | J9: 0 | K9: 0 | L9: 0 | M9: 0 | N9: 0 | O9: 0 | P9: 0 | Q9: 0 | R9: 0 | S9: 1 | T9: 1 | U9: 0 | V9: 0 | W9: 1 | X9: 1 | Y9: 0 | Z9: 0 | AA9: 1 | AB9: 0 | AC9: 1 | AD9: 1 | AE9: 1 | AF9: 2 | AG9: 0 | AH9: 1 | AI9: 2
A10: 8 | B10: 安徽省 | C10: 淮北市 | D10: 0 | E10: 0 | F10: 0 | G10: 0 | H10: 0 | I10: 0 | J10: 0 | K10: 0 | L10: 0 | M10: 0 | N10: 0 | O10: 0 | P10: 0 | Q10: 0 | R10: 0 | S10: 0 | T10: 0 | U10: 0 | V10: 0 | W10: 0 | X10: 0 | Y10: 0 | Z10: 0 | AA10: 0 | AB10: 0 | AC10: 0 | AD10: 0 | AE10: 0 | AF10: 0 | AG10: 0 | AH10: 0 | AI10: 1
A11: 9 | B11: 安徽省 | C11: 淮南市 | D11: 0 | E11: 0 | F11: 0 | G11: 0 | H11: 0 | I11: 0 | J11: 0 | K11: 0 | L11: 0 | M11: 0 | N11: 0 | O11: 0 | P11: 0 | Q11: 0 | R11: 0 | S11: 0 | T11: 0 | U11: 0 | V11: 0 | W11: 0 | X11: 0 | Y11: 0 | Z11: 0 | AA11: 0 | AB11: 0 | AC11: 0 | AD11: 0 | AE11: 1 | AF11: 0 | AG11: 3 | AH11: 0 | AI11: 1
A12: 10 | B12: 安徽省 | C12: 黄山市 | D12: 0 | E12: 0 | F12: 0 | G12: 0 | H12: 1 | I12: 0 | J12: 0 | K12: 0 | L12: 0 | M12: 0 | N12: 0 | O12: 0 | P12: 2 | Q12: 0 | R12: 0 | S12: 0 | T12: 1 | U12: 0 | V12: 0 | W12: 0 | X12: 1 | Y12: 0 | Z12: 0 | AA12: 0 | AB12: 0 | AC12: 0 | AD12: 0 | AE12: 0 | AF12: 0 | AG12: 0 | AH12: 0 | AI12: 0
A13: 11 | B13: 安徽省 | C13: 六安市 | D13: 0 | E13: 0 | F13: 0 | G13: 0 | H13: 1 | I13: 0 | J13: 0 | K13: 0 | L13: 0 | M13: 0 | N13: 0 | O13: 0 | P13: 0 | Q13: 0 | R13: 0 | S13: 0 | T13: 0 | U13: 0 | V13: 0 | W13: 0 | X13: 0 | Y13: 0 | Z13: 0 | AA13: 0 | AB13: 0 | AC13: 1 | AD13: 0 | AE13: 0 | AF13: 0 | AG13: 1 | AH13: 2 | AI13: 1
... A290: 288 | B290: 重庆市 | C290: 重庆市 | D290: 0 | E290: 3 | F290: 0 | G290: 1 | H290: 2 | I290: 0 | J290: 0 | K290: 0 | L290: 0 | M290: 0 | N290: 0 | O290: 0 | P290: 0 | Q290: 0 | R290: 0 | S290: 0 | T290: 3 | U290: 0 | V290: 3 | W290: 2 | X290: 1 | Y290: 2 | Z290: 0 | AA290: 2 | AB290: 0 | AC290: 1 | AD290: 2 | AE290: 4 | AF290: 4 | AG290: 1 | AH290: 1 | AI290: 2

Sheet 地级市累计
B1: 省 | C1: 市 | D1: 1948 | E1: 1955 | F1: 1956 | G1: 1957 | H1: 1980 | I1: 1983 | J1: 1984 | K1: 1985 | L1: 1986 | M1: 1988 | N1: 1989 | O1: 1990 | P1: 1991 | Q1: 1992 | R1: 1993 | S1: 1994 | T1: 1995 | U1: 1996 | V1: 1997 | W1: 1999 | X1: 2001 | Y1: 2003 | Z1: 2004 | AA1: 2005 | AB1: 2007 | AC1: 2009 | AD1: 2011 | AE1: 2013 | AF1: 2015 | AG1: 2017 | AH1: 2019 | AI1: 2021
A2: 0 | B2: 安徽省 | C2: 安庆市 | D2: 0 | E2: =D2+地级市!E2 -> 2 | F2: =E2+地级市!F2 -> 2 | G2: =F2+地级市!G2 -> 2 | H2: =G2+地级市!H2 -> 5 | I2: =H2+地级市!I2 -> 5 | J2: =I2+地级市!J2 -> 5 | K2: =J2+地级市!K2 -> 5 | L2: =K2+地级市!L2 -> 5 | ... AI2: =AH2+地级市!AI2 -> 27
A3: 1 | B3: 安徽省 | C3: 蚌埠市 | D3: 0 | E3: =D3+地级市!E3 -> 0 | F3: =E3+地级市!F3 -> 0 | G3: =F3+地级市!G3 -> 0 | H3: =G3+地级市!H3 -> 0 | I3: =H3+地级市!I3 -> 0 | J3: =I3+地级市!J3 -> 0 | K3: =J3+地级市!K3 -> 0 | L3: =K3+地级市!L3 -> 0 | ... AI3: =AH3+地级市!AI3 -> 3
A4: 2 | B4: 安徽省 | C4: 亳州市 | D4: 0 | E4: =D4+地级市!E4 -> 0 | F4: =E4+地级市!F4 -> 0 | G4: =F4+地级市!G4 -> 0 | H4: =G4+地级市!H4 -> 0 | I4: =H4+地级市!I4 -> 0 | J4: =I4+地级市!J4 -> 0 | K4: =J4+地级市!K4 -> 0 | L4: =K4+地级市!L4 -> 0 | ... AI4: =AH4+地级市!AI4 -> 3
A5: 3 | B5: 安徽省 | C5: 池州市 | D5: 0 | E5: =D5+地级市!E5 -> 0 | F5: =E5+地级市!F5 -> 0 | G5: =F5+地级市!G5 -> 0 | H5: =G5+地级市!H5 -> 0 | I5: =H5+地级市!I5 -> 0 | J5: =I5+地级市!J5 -> 0 | K5: =J5+地级市!K5 -> 0 | L5: =K5+地级市!L5 -> 0 | ... AI5: =AH5+地级市!AI5 -> 1
A6: 4 | B6: 安徽省 | C6: 滁州市 | D6: 0 | E6: =D6+地级市!E6 -> 0 | F6: =E6+地级市!F6 -> 0 | G6: =F6+地级市!G6 -> 0 | H6: =G6+地级市!H6 -> 2 | I6: =H6+地级市!I6 -> 2 | J6: =I6+地级市!J6 -> 2 | K6: =J6+地级市!K6 -> 2 | L6: =K6+地级市!L6 -> 2 | ... AI6: =AH6+地级市!AI6 -> 10
A7: 5 | B7: 安徽省 | C7: 阜阳市 | D7: 0 | E7: =D7+地级市!E7 -> 0 | F7: =E7+地级市!F7 -> 0 | G7: =F7+地级市!G7 -> 0 | H7: =G7+地级市!H7 -> 0 | I7: =H7+地级市!I7 -> 0 | J7: =I7+地级市!J7 -> 0 | K7: =J7+地级市!K7 -> 0 | L7: =K7+地级市!L7 -> 0 | ... AI7: =AH7+地级市!AI7 -> 7
A8: 6 | B8: 安徽省 | C8: 阜阳市 | D8: 0 | E8: =D8+地级市!E8 -> 0 | F8: =E8+地级市!F8 -> 0 | G8: =F8+地级市!G8 -> 0 | H8: =G8+地级市!H8 -> 0 | I8: =H8+地级市!I8 -> 0 | J8: =I8+地级市!J8 -> 0 | K8: =J8+地级市!K8 -> 0 | L8: =K8+地级市!L8 -> 0 | ... AI8: =AH8+地级市!AI8 -> 7
A9: 7 | B9: 安徽省 | C9: 合肥市 | D9: 0 | E9: =D9+地级市!E9 -> 0 | F9: =E9+地级市!F9 -> 0 | G9: =F9+地级市!G9 -> 0 | H9: =G9+地级市!H9 -> 2 | I9: =H9+地级市!I9 -> 2 | J9: =I9+地级市!J9 -> 2 | K9: =J9+地级市!K9 -> 2 | L9: =K9+地级市!L9 -> 2 | ... AI9: =AH9+地级市!AI9 -> 15
A10: 8 | B10: 安徽省 | C10: 淮北市 | D10: 0 | E10: =D10+地级市!E10 -> 0 | F10: =E10+地级市!F10 -> 0 | G10: =F10+地级市!G10 -> 0 | H10: =G10+地级市!H10 -> 0 | I10: =H10+地级市!I10 -> 0 | J10: =I10+地级市!J10 -> 0 | K10: =J10+地级市!K10 -> 0 | L10: =K10+地级市!L10 -> 0 | ... AI10: =AH10+地级市!AI10 -> 1
A11: 9 | B11: 安徽省 | C11: 淮南市 | D11: 0 | E11: =D11+地级市!E11 -> 0 | F11: =E11+地级市!F11 -> 0 | G11: =F11+地级市!G11 -> 0 | H11: =G11+地级市!H11 -> 0 | I11: =H11+地级市!I11 -> 0 | J11: =I11+地级市!J11 -> 0 | K11: =J11+地级市!K11 -> 0 | L11: =K11+地级市!L11 -> 0 | ... AI11: =AH11+地级市!AI11 -> 5
A12: 10 | B12: 安徽省 | C12: 黄山市 | D12: 0 | E12: =D12+地级市!E12 -> 0 | F12: =E12+地级市!F12 -> 0 | G12: =F12+地级市!G12 -> 0 | H12: =G12+地级市!H12 -> 1 | I12: =H12+地级市!I12 -> 1 | J12: =I12+地级市!J12 -> 1 | K12: =J12+地级市!K12 -> 1 | L12: =K12+地级市!L12 -> 1 | ... AI12: =AH12+地级市!AI12 -> 5
A13: 11 | B13: 安徽省 | C13: 六安市 | D13: 0 | E13: =D13+地级市!E13 -> 0 | F13: =E13+地级市!F13 -> 0 | G13: =F13+地级市!G13 -> 0 | H13: =G13+地级市!H13 -> 1 | I13: =H13+地级市!I13 -> 1 | J13: =I13+地级市!J13 -> 1 | K13: =J13+地级市!K13 -> 1 | L13: =K13+地级市!L13 -> 1 | ... AI13: =AH13+地级市!AI13 -> 6
... A290: 288 | B290: 重庆市 | C290: 重庆市 | D290: 0 | E290: =D290+地级市!E290 -> 3 | F290: =E290+地级市!F290 -> 3 | G290: =F290+地级市!G290 -> 4 | H290: =G290+地级市!H290 -> 6 | I290: =H290+地级市!I290 -> 6 | J290: =I290+地级市!J290 -> 6 | K290: =J290+地级市!K290 -> 6 | L290: =K290+地级市!L290 -> 6 | ... AI290: =AH290+地级市!AI290 -> 34
