Workbook

Sheet 科学院
A1: 继承院校 | B1: 毕业院校 | C1: 1948 | D1: 1955 | E1: 1957 | F1: 1980 | G1: 1991 | H1: 1993 | I1: 1995 | J1: 1997 | K1: 1999 | L1: 2001 | M1: 2003 | N1: 2005 | O1: 2007 | P1: 2009 | Q1: 2011 | R1: 2013 | S1: 2015 | T1: 2017 | U1: 2019 | V1: 2021
B2: 华中大学 | C2: 0 | D2: 0 | E2: 0 | F2: 0 | G2: 0 | H2: 1 | I2: 1 | J2: 1 | K2: 1 | L2: 1 | M2: 1 | N2: 1 | O2: 1 | P2: 1 | Q2: 1 | R2: 1 | S2: 1 | T2: 1 | U2: 1 | V2: 1
B3: 安徽大学 | C3: 0 | D3: 0 | E3: 0 | F3: 0 | G3: 0 | H3: 0 | I3: 0 | J3: 0 | K3: 0 | L3: 0 | M3: 0 | N3: 0 | O3: 1 | P3: 1 | Q3: 1 | R3: 1 | S3: 1 | T3: 1 | U3: 1 | V3: 1
B4: 安徽教育学院 | C4: 0 | D4: 0 | E4: 0 | F4: 0 | G4: 0 | H4: 0 | I4: 0 | J4: 0 | K4: 0 | L4: 0 | M4: 0 | N4: 0 | O4: 0 | P4: 0 | Q4: 1 | R4: 1 | S4: 1 | T4: 1 | U4: 1 | V4: 1
B5: 安徽农学院 | C5: 0 | D5: 0 | E5: 0 | F5: 0 | G5: 0 | H5: 0 | I5: 0 | J5: 0 | K5: 0 | L5: 1 | M5: 1 | N5: 1 | O5: 1 | P5: 1 | Q5: 1 | R5: 1 | S5: 1 | T5: 1 | U5: 1 | V5: 1
B6: 安徽农业大学 | C6: 0 | D6: 0 | E6: 0 | F6: 0 | G6: 0 | H6: 0 | I6: 0 | J6: 0 | K6: 0 | L6: 0 | M6: 0 | N6: 1 | O6: 1 | P6: 1 | Q6: 1 | R6: 1 | S6: 1 | T6: 1 | U6: 1 | V6: 1
B7: 安徽师范大学 | C7: 0 | D7: 0 | E7: 0 | F7: 0 | G7: 0 | H7: 0 | I7: 0 | J7: 0 | K7: 0 | L7: 0 | M7: 0 | N7: 0 | O7: 0 | P7: 0 | Q7: 1 | R7: 2 | S7: 3 | T7: 3 | U7: 3 | V7: 3
B8: 白求恩医科大学 | C8: 0 | D8: 0 | E8: 0 | F8: 0 | G8: 0 | H8: 0 | I8: 0 | J8: 0 | K8: 0 | L8: 0 | M8: 0 | N8: 0 | O8: 0 | P8: 0 | Q8: 1 | R8: 2 | S8: 2 | T8: 2 | U8: 2 | V8: 2
B9: 蚌埠医学院 | C9: 0 | D9: 0 | E9: 0 | F9: 0 | G9: 0 | H9: 0 | I9: 0 | J9: 0 | K9: 0 | L9: 0 | M9: 0 | N9: 0 | O9: 1 | P9: 1 | Q9: 1 | R9: 1 | S9: 3 | T9: 3 | U9: 3 | V9: 3
A10: 交通大学 | B10: 北方交通大学 | C10: 0 | D10: 0 | E10: 0 | F10: 0 | G10: 0 | H10: 0 | I10: 0 | J10: 0 | K10: 0 | L10: 1 | M10: 1 | N10: 1 | O10: 1 | P10: 1 | Q10: 1 | R10: 1 | S10: 1 | T10: 1 | U10: 1 | V10: 1
A11: 北京大学 | B11: 北京大学 | C11: 3 | D11: 19 | E11: 22 | F11: 50 | G11: 72 | H11: 81 | I11: 91 | J11: 105 | K11: 114 | L11: 124 | M11: 129 | N11: 133 | O11: 134 | P11: 136 | Q11: 141 | R11: 148 | S11: 151 | T11: 156 | U11: 158 | V11: 163
A12: 中国地质大学 | B12: 北京地质学院 | C12: 0 | D12: 0 | E12: 0 | F12: 0 | G12: 6 | H12: 9 | I12: 11 | J12: 14 | K12: 14 | L12: 15 | M12: 16 | N12: 18 | O12: 18 | P12: 19 | Q12: 19 | R12: 19 | S12: 19 | T12: 19 | U12: 19 | V12: 19
B13: 北京辅仁大学 | C13: 0 | D13: 0 | E13: 0 | F13: 0 | G13: 0 | H13: 0 | I13: 0 | J13: 0 | K13: 1 | L13: 1 | M13: 1 | N13: 1 | O13: 1 | P13: 1 | Q13: 1 | R13: 1 | S13: 1 | T13: 1 | U13: 1 | V13: 1
B14: 北京钢铁学院 | C14: 0 | D14: 0 | E14: 0 | F14: 0 | G14: 1 | H14: 2 | I14: 2 | J14: 2 | K14: 2 | L14: 2 | M14: 2 | N14: 2 | O14: 2 | P14: 2 | Q14: 2 | R14: 2 | S14: 2 | T14: 2 | U14: 2 | V14: 2
B15: 北京航空航天大学 | C15: 0 | D15: 0 | E15: 0 | F15: 0 | G15: 0 | H15: 0 | I15: 0 | J15: 0 | K15: 0 | L15: 0 | M15: 0 | N15: 0 | O15: 0 | P15: 0 | Q15: 0 | R15: 1 | S15: 1 | T15: 1 | U15: 1 | V15: 2
B16: 北京航空学院 | C16: 0 | D16: 0 | E16: 0 | F16: 0 | G16: 0 | H16: 0 | I16: 0 | J16: 0 | K16: 2 | L16: 2 | M16: 2 | N16: 2 | O16: 2 | P16: 2 | Q16: 2 | R16: 2 | S16: 2 | T16: 2 | U16: 2 | V16: 3
B17: 北京化工学院 | C17: 0 | D17: 0 | E17: 0 | F17: 0 | G17: 0 | H17: 0 | I17: 0 | J17: 0 | K17: 0 | L17: 0 | M17: 0 | N17: 0 | O17: 0 | P17: 0 | Q17: 0 | R17: 0 | S17: 1 | T17: 1 | U17: 1 | V17: 1
B18: 北京科技大学 | C18: 0 | D18: 0 | E18: 0 | F18: 0 | G18: 0 | H18: 1 | I18: 2 | J18: 2 | K18: 2 | L18: 2 | M18: 2 | N18: 2 | O18: 2 | P18: 2 | Q18: 2 | R18: 2 | S18: 2 | T18: 2 | U18: 2 | V18: 2
B19: 北京矿业学院 | C19: 0 | D19: 0 | E19: 0 | F19: 0 | G19: 1 | H19: 1 | I19: 1 | J19: 1 | K19: 1 | L19: 1 | M19: 1 | N19: 1 | O19: 1 | P19: 1 | Q19: 1 | R19: 1 | S19: 1 | T19: 1 | U19: 1 | V19: 1
B20: 北京理工大学 | C20: 0 | D20: 0 | E20: 0 | F20: 0 | G20: 0 | H20: 0 | I20: 0 | J20: 0 | K20: 0 | L20: 0 | M20: 0 | N20: 0 | O20: 1 | P20: 1 | Q20: 1 | R20: 1 | S20: 1 | T20: 1 | U20: 1 | V20: 1
B21: 北京林学院 | C21: 0 | D21: 0 | E21: 0 | F21: 0 | G21: 2 | H21: 2 | I21: 3 | J21: 3 | K21: 3 | L21: 3 | M21: 3 | N21: 3 | O21: 3 | P21: 3 | Q21: 3 | R21: 3 | S21: 3 | T21: 3 | U21: 3 | V21: 3
B22: 北京农业大学 | C22: 0 | D22: 1 | E22: 1 | F22: 1 | G22: 4 | H22: 5 | I22: 7 | J22: 7 | K22: 7 | L22: 8 | M22: 8 | N22: 8 | O22: 8 | P22: 8 | Q22: 8 | R22: 8 | S22: 8 | T22: 8 | U22: 8 | V22: 8
B23: 北京师范大学 | C23: 0 | D23: 0 | E23: 1 | F23: 3 | G23: 3 | H23: 5 | I23: 5 | J23: 5 | K23: 5 | L23: 5 | M23: 7 | N23: 7 | O23: 7 | P23: 7 | Q23: 8 | R23: 8 | S23: 9 | T23: 9 | U23: 9 | V23: 10
B24: 北京石油学院 | C24: 0 | D24: 0 | E24: 0 | F24: 0 | G24: 1 | H24: 1 | I24: 1 | J24: 2 | K24: 2 | L24: 2 | M24: 2 | N24: 3 | O24: 3 | P24: 3 | Q24: 3 | R24: 3 | S24: 3 | T24: 3 | U24: 3 | V24: 3
... B27: 北京协和医学院 | C27: 0 | D27: 4 | E27: 4 | F27: 5 | G27: 5 | H27: 5 | I27: 5 | J27: 5 | K27: 5 | L27: 5 | M27: 5 | N27: 5 | O27: 5 | P27: 5 | Q27: 5 | R27: 5 | S27: 5 | T27: 5 | U27: 5 | V27: 5
A28: 北京大学 | B28: 北京医科大学 | C28: 0 | D28: 0 | E28: 0 | F28: 0 | G28: 0 | H28: 0 | I28: 0 | J28: 0 | K28: 0 | L28: 0 | M28: 0 | N28: 0 | O28: 0 | P28: 0 | Q28: 0 | R28: 0 | S28: 0 | T28: 0 | U28: 1 | V28: 1
A29: 北京大学 | B29: 北京医学院 | C29: 0 | D29: 0 | E29: 0 | F29: 0 | G29: 0 | H29: 0 | I29: 2 | J29: 2 | K29: 2 | L29: 2 | M29: 2 | N29: 3 | O29: 3 | P29: 3 | Q29: 3 | R29: 3 | S29: 3 | T29: 3 | U29: 3 | V29: 3
B30: 北京中法大学 | C30: 0 | D30: 0 | E30: 0 | F30: 1 | G30: 1 | H30: 1 | I30: 1 | J30: 1 | K30: 1 | L30: 1 | M30: 1 | N30: 1 | O30: 1 | P30: 1 | Q30: 1 | R30: 1 | S30: 1 | T30: 1 | U30: 1 | V30: 1
B31: 北平大学 | C31: 0 | D31: 1 | E31: 1 | F31: 3 | G31: 3 | H31: 3 | I31: 4 | J31: 4 | K31: 4 | L31: 4 | M31: 4 | N31: 4 | O31: 4 | P31: 4 | Q31: 4 | R31: 4 | S31: 4 | T31: 4 | U31: 4 | V31: 4
B32: 北洋大学 | C32: 0 | D32: 2 | E32: 2 | F32: 4 | G32: 5 | H32: 6 | I32: 6 | J32: 6 | K32: 6 | L32: 6 | M32: 6 | N32: 6 | O32: 6 | P32: 6 | Q32: 6 | R32: 6 | S32: 6 | T32: 6 | U32: 6 | V32: 6
B33: 北洋工学院 | C33: 0 | D33: 0 | E33: 0 | F33: 2 | G33: 2 | H33: 2 | I33: 2 | J33: 2 | K33: 2 | L33: 2 | M33: 2 | N33: 2 | O33: 2 | P33: 2 | Q33: 2 | R33: 2 | S33: 2 | T33: 2 | U33: 2 | V33: 2
B34: 兵工学校大学 | C34: 0 | D34: 0 | E34: 0 | F34: 0 | G34: 1 | H34: 1 | I34: 1 | J34: 1 | K34: 1 | L34: 1 | M34: 1 | N34: 1 | O34: 1 | P34: 1 | Q34: 1 | R34: 1 | S34: 1 | T34: 1 | U34: 1 | V34: 1
B35: 成都地质学院 | C35: 0 | D35: 0 | E35: 0 | F35: 0 | G35: 0 | H35: 0 | I35: 0 | J35: 0 | K35: 0 | L35: 0 | M35: 0 | N35: 0 | O35: 0 | P35: 0 | Q35: 0 | R35: 1 | S35: 1 | T35: 1 | U35: 1 | V35: 2
B36: 成都电讯工程学院 | C36: 0 | D36: 0 | E36: 0 | F36: 0 | G36: 0 | H36: 0 | I36: 0 | J36: 0 | K36: 0 | L36: 1 | M36: 1 | N36: 1 | O36: 1 | P36: 1 | Q36: 1 | R36: 1 | S36: 1 | T36: 1 | U36: 1 | V36: 1
B37: 成都华西协和大学 | C37: 0 | D37: 1 | E37: 1 | F37: 1 | G37: 1 | H37: 1 | I37: 1 | J37: 1 | K37: 1 | L37: 1 | M37: 1 | N37: 1 | O37: 1 | P37: 1 | Q37: 1 | R37: 1 | S37: 1 | T37: 1 | U37: 1 | V37: 1
B38: 成都科技大学 | C38: 0 | D38: 0 | E38: 0 | F38: 0 | G38: 0 | H38: 0 | I38: 0 | J38: 0 | K38: 0 | L38: 0 | M38: 0 | N38: 0 | O38: 0 | P38: 0 | Q38: 0 | R38: 0 | S38: 0 | T38: 0 | U38: 1 | V38: 1
B39: 大连大学 | C39: 0 | D39: 0 | E39: 0 | F39: 0 | G39: 1 | H39: 1 | I39: 1 | J39: 1 | K39: 1 | L39: 1 | M39: 1 | N39: 1 | O39: 1 | P39: 1 | Q39: 1 | R39: 1 | S39: 1 | T39: 1 | U39: 1 | V39: 1
B40: 大连工学院 | C40: 0 | D40: 0 | E40: 0 | F40: 0 | G40: 1 | H40: 2 | I40: 2 | J40: 2 | K40: 2 | L40: 2 | M40: 2 | N40: 2 | O40: 2 | P40: 3 | Q40: 3 | R40: 3 | S40: 3 | T40: 3 | U40: 4 | V40: 4
B41: 大连理工大学 | C41: 0 | D41: 0 | E41: 0 | F41: 0 | G41: 0 | H41: 0 | I41: 0 | J41: 0 | K41: 0 | L41: 0 | M41: 0 | N41: 0 | O41: 0 | P41: 0 | Q41: 0 | R41: 0 | S41: 0 | T41: 1 | U41: 2 | V41: 2
... B61: 东京第一高等学校 | C61: 1 | D61: 1 | E61: 1 | F61: 1 | G61: 1 | H61: 1 | I61: 1 | J61: 1 | K61: 1 | L61: 1 | M61: 1 | N61: 1 | O61: 1 | P61: 1 | Q61: 1 | R61: 1 | S61: 1 | T61: 1 | U61: 1 | V61: 1
...

Sheet 工程院
A1: 继承院校 | B1: 毕业院校 | C1: 1994 | D1: 1995 | E1: 1996 | F1: 1997 | G1: 1999 | H1: 2001 | I1: 2003 | J1: 2005 | K1: 2007 | L1: 2009 | M1: 2011 | N1: 2013 | O1: 2015 | P1: 2017 | Q1: 2019 | R1: 2021
A2: 清华大学 | B2: 清华大学 | C2: 15 | D2: 33 | E2: 33 | F2: 42 | G2: 55 | H2: 65 | I2: 68 | J2: 73 | K2: 75 | L2: 78 | M2: 81 | N2: 84 | O2: 90 | P2: 93 | Q2: 98 | R2: 99
A3: 北京大学 | B3: 北京大学 | C3: 8 | D3: 19 | E3: 20 | F3: 25 | G3: 27 | H3: 29 | I3: 31 | J3: 34 | K3: 34 | L3: 36 | M3: 38 | N3: 38 | O3: 40 | P3: 41 | Q3: 44 | R3: 44
A4: 交通大学 | B4: 北方交通大学 | C4: 0 | D4: 0 | E4: 0 | F4: 0 | G4: 0 | H4: 0 | I4: 0 | J4: 0 | K4: 0 | L4: 0 | M4: 0 | N4: 0 | O4: 0 | P4: 1 | Q4: 1 | R4: 1
A5: 交通大学 | B5: 交通大学 | C5: 4 | D5: 9 | E5: 9 | F5: 11 | G5: 11 | H5: 11 | I5: 12 | J5: 12 | K5: 12 | L5: 12 | M5: 12 | N5: 12 | O5: 12 | P5: 12 | Q5: 12 | R5: 12
A6: 交通大学 | B6: 上海第二医科大学 | C6: 0 | D6: 0 | E6: 0 | F6: 0 | G6: 0 | H6: 0 | I6: 0 | J6: 0 | K6: 0 | L6: 0 | M6: 0 | N6: 0 | O6: 2 | P6: 2 | Q6: 2 | R6: 3
A7: 交通大学 | B7: 上海交通大学 | C7: 7 | D7: 20 | E7: 21 | F7: 27 | G7: 30 | H7: 34 | I7: 36 | J7: 37 | K7: 37 | L7: 37 | M7: 39 | N7: 42 | O7: 42 | P7: 42 | Q7: 44 | R7: 45
A8: 交通大学 | B8: 唐山交通大学 | C8: 1 | D8: 2 | E8: 2 | F8: 2 | G8: 2 | H8: 2 | I8: 2 | J8: 2 | K8: 2 | L8: 2 | M8: 2 | N8: 2 | O8: 2 | P8: 2 | Q8: 2 | R8: 2
A9: 交通大学 | B9: 西安交通大学 | C9: 1 | D9: 2 | E9: 2 | F9: 5 | G9: 6 | H9: 7 | I9: 8 | J9: 9 | K9: 9 | L9: 9 | M9: 9 | N9: 9 | O9: 10 | P9: 11 | Q9: 13 | R9: 13
A10: 交通大学 | B10: 西南交通大学 | C10: 0 | D10: 0 | E10: 0 | F10: 0 | G10: 0 | H10: 0 | I10: 0 | J10: 0 | K10: 0 | L10: 2 | M10: 2 | N10: 2 | O10: 2 | P10: 3 | Q10: 3 | R10: 3
A11: 交通大学 | B11: 上海圣约翰大学 | C11: 2 | D11: 2 | E11: 2 | F11: 2 | G11: 3 | H11: 3 | I11: 3 | J11: 3 | K11: 3 | L11: 3 | M11: 3 | N11: 3 | O11: 3 | P11: 3 | Q11: 3 | R11: 3
A12: 复旦大学 | B12: 复旦大学 | C12: 1 | D12: 6 | E12: 6 | F12: 10 | G12: 12 | H12: 12 | I12: 13 | J12: 13 | K12: 14 | L12: 14 | M12: 14 | N12: 15 | O12: 15 | P12: 15 | Q12: 15 | R12: 16
... A29: 哈尔滨工业大学 | B29: 哈尔滨工业大学 | C29: 1 | D29: 10 | E29: 10 | F29: 12 | G29: 16 | H29: 20 | I29: 24 | J29: 25 | K29: 26 | L29: 28 | M29: 29 | N29: 29 | O29: 31 | P29: 33 | Q29: 36 | R29: 39
B30: （法国）巴黎南大学 | C30: 0 | D30: 0 | E30: 0 | F30: 0 | G30: 0 | H30: 0 | I30: 0 | J30: 0 | K30: 0 | L30: 1 | M30: 1 | N30: 1 | O30: 1 | P30: 1 | Q30: 1 | R30: 1
B31: 爱尔兰国立大学 | C31: 0 | D31: 0 | E31: 0 | F31: 0 | G31: 0 | H31: 0 | I31: 0 | J31: 0 | K31: 0 | L31: 3 | M31: 3 | N31: 3 | O31: 3 | P31: 3 | Q31: 3 | R31: 3
B32: 安徽大学 | C32: 0 | D32: 1 | E32: 1 | F32: 1 | G32: 1 | H32: 1 | I32: 1 | J32: 1 | K32: 1 | L32: 1 | M32: 1 | N32: 1 | O32: 1 | P32: 1 | Q32: 1 | R32: 1
B33: 安徽理工大学 | C33: 0 | D33: 0 | E33: 0 | F33: 0 | G33: 0 | H33: 0 | I33: 0 | J33: 0 | K33: 0 | L33: 1 | M33: 1 | N33: 1 | O33: 1 | P33: 1 | Q33: 1 | R33: 1
B34: 安徽师范大学 | C34: 0 | D34: 0 | E34: 0 | F34: 0 | G34: 0 | H34: 0 | I34: 0 | J34: 0 | K34: 0 | L34: 0 | M34: 1 | N34: 1 | O34: 1 | P34: 1 | Q34: 1 | R34: 1
B35: 白求恩医科大学 | C35: 0 | D35: 0 | E35: 0 | F35: 0 | G35: 0 | H35: 0 | I35: 0 | J35: 0 | K35: 0 | L35: 0 | M35: 1 | N35: 1 | O35: 1 | P35: 2 | Q35: 2 | R35: 2
B36: 百泉农业专科学校 | C36: 0 | D36: 0 | E36: 0 | F36: 0 | G36: 0 | H36: 0 | I36: 0 | J36: 0 | K36: 0 | L36: 0 | M36: 0 | N36: 0 | O36: 1 | P36: 1 | Q36: 1 | R36: 1
B37: 包头医学院 | C37: 0 | D37: 0 | E37: 0 | F37: 0 | G37: 0 | H37: 0 | I37: 0 | J37: 0 | K37: 0 | L37: 0 | M37: 0 | N37: 0 | O37: 1 | P37: 1 | Q37: 1 | R37: 1
B38: 北京地质学院 | C38: 0 | D38: 1 | E38: 1 | F38: 3 | G38: 3 | H38: 3 | I38: 3 | J38: 3 | K38: 3 | L38: 3 | M38: 3 | N38: 3 | O38: 3 | P38: 3 | Q38: 3 | R38: 3
B39: 北京辅仁大学 | C39: 0 | D39: 1 | E39: 1 | F39: 1 | G39: 1 | H39: 1 | I39: 1 | J39: 1 | K39: 1 | L39: 1 | M39: 1 | N39: 1 | O39: 1 | P39: 1 | Q39: 1 | R39: 1
B40: 北京钢铁工业学院 | C40: 2 | D40: 4 | E40: 4 | F40: 8 | G40: 9 | H40: 10 | I40: 10 | J40: 11 | K40: 11 | L40: 11 | M40: 11 | N40: 11 | O40: 11 | P40: 11 | Q40: 11 | R40: 11
B41: 北京钢铁学院 | C41: 0 | D41: 0 | E41: 0 | F41: 1 | G41: 1 | H41: 1 | I41: 1 | J41: 1 | K41: 1 | L41: 1 | M41: 1 | N41: 1 | O41: 1 | P41: 1 | Q41: 1 | R41: 1
... B341: 西南财经大学 | C341: 0 | D341: 0 | E341: 0 | F341: 0 | G341: 0 | H341: 0 | I341: 0 | J341: 0 | K341: 0 | L341: 0 | M341: 0 | N341: 0 | O341: 1 | P341: 1 | Q341: 1 | R341: 1
A342: 拆分 | B342: 西南联合大学 | C342: 2 | D342: 5 | E342: 5 | F342: 5 | G342: 5 | H342: 5 | I342: 5 | J342: 5 | K342: 5 | L342: 5 | M342: 5 | N342: 5 | O342: 5 | P342: 5 | Q342: 5 | R342: 5
B343: 西南农学院 | C343: 0 | D343: 2 | E343: 2 | F343: 2 | G343: 3 | H343: 3 | I343: 3 | J343: 3 | K343: 3 | L343: 3 | M343: 3 | N343: 3 | O343: 3 | P343: 3 | Q343: 3 | R343: 3
B344: 西南石油大学 | C344: 0 | D344: 0 | E344: 0 | F344: 0 | G344: 0 | H344: 0 | I344: 0 | J344: 0 | K344: 0 | L344: 1 | M344: 1 | N344: 1 | O344: 1 | P344: 2 | Q344: 2 | R344: 2
B345: 希腊克里特大学 | C345: 0 | D345: 0 | E345: 0 | F345: 0 | G345: 0 | H345: 0 | I345: 0 | J345: 0 | K345: 0 | L345: 0 | M345: 0 | N345: 1 | O345: 1 | P345: 1 | Q345: 1 | R345: 1
B346: 现日本东京农工大学 | C346: 0 | D346: 1 | E346: 1 | F346: 1 | G346: 1 | H346: 1 | I346: 1 | J346: 1 | K346: 1 | L346: 1 | M346: 1 | N346: 1 | O346: 1 | P346: 1 | Q346: 1 | R346: 1
B347: 香港大学 | C347: 0 | D347: 0 | E347: 0 | F347: 0 | G347: 0 | H347: 0 | I347: 0 | J347: 1 | K347: 2 | L347: 2 | M347: 2 | N347: 2 | O347: 2 | P347: 2 | Q347: 2 | R347: 2
B348: 新风加工厂职工业余大学 | C348: 0 | D348: 0 | E348: 0 | F348: 0 | G348: 1 | H348: 1 | I348: 1 | J348: 1 | K348: 1 | L348: 1 | M348: 1 | N348: 1 | O348: 1 | P348: 1 | Q348: 1 | R348: 1
B349: 新疆兵团奎屯农校 | C349: 0 | D349: 0 | E349: 0 | F349: 0 | G349: 0 | H349: 0 | I349: 0 | J349: 0 | K349: 0 | L349: 0 | M349: 0 | N349: 1 | O349: 1 | P349: 1 | Q349: 1 | R349: 1
B350: 新疆大学 | C350: 0 | D350: 0 | E350: 0 | F350: 0 | G350: 0 | H350: 0 | I350: 0 | J350: 0 | K350: 0 | L350: 0 | M350: 1 | N350: 1 | O350: 1 | P350: 1 | Q350: 1 | R350: 1
B351: 新西兰奥塔哥大学 | C351: 0 | D351: 0 | E351: 0 | F351: 0 | G351: 0 | H351: 0 | I351: 0 | J351: 0 | K351: 0 | L351: 0 | M351: 0 | N351: 1 | O351: 1 | P351: 1 | Q351: 1 | R351: 1
B352: 新西兰梅西大学 | C352: 0 | D352: 0 | E352: 0 | F352: 0 | G352: 0 | H352: 0 | I352: 0 | J352: 0 | K352: 0 | L352: 1 | M352: 1 | N352: 1 | O352: 1 | P352: 1 | Q352: 1 | R352: 1
A353: 拆分 | B353: 燕京大学 | C353: 2 | D353: 3 | E353: 3 | F353: 3 | G353: 3 | H353: 3 | I353: 3 | J353: 3 | K353: 3 | L353: 3 | M353: 3 | N353: 3 | O353: 3 | P353: 3 | Q353: 3 | R353: 3
B354: 燕山大学 | C354: 0 | D354: 0 | E354: 0 | F354: 0 | G354: 0 | H354: 0 | I354: 0 | J354: 0 | K354: 0 | L354: 0 | M354: 0 | N354: 0 | O354: 0 | P354: 1 | Q354: 1 | R354: 1
B355: 英国爱丁堡大学 | C355: 0 | D355: 0 | E355: 1 | F355: 1 | G355: 1 | H355: 1 | I355: 1 | J355: 1 | K355: 1 | L355: 1 | M355: 1 | N355: 1 | O355: 1 | P355: 1 | Q355: 1 | R355: 1
...

Sheet 总表
A1: 毕业院校 | B1: 1948 | C1: 1955 | D1: 1957 | E1: 1980 | F1: 1991 | G1: 1993 | H1: 1994 | I1: 1995 | J1: 1997 | K1: 1999 | L1: 2001 | M1: 2003 | N1: 2005 | O1: 2007 | P1: 2009 | Q1: 2011 | R1: 2013 | S1: 2015 | T1: 2017 | U1: 2019 | V1: 2021
A2: 华中大学 | B2: =IF(COUNTIF(科学院!$B:$B,总表!$A2),INDEX(科学院!C:C,MATCH(总表!$A2,科学院!$B:$B,0)),0) -> 0 | C2: =IF(COUNTIF(科学院!$B:$B,总表!$A2),INDEX(科学院!D:D,MATCH(总表!$A2,科学院!$B:$B,0)),0) -> 0 | D2: =IF(COUNTIF(科学院!$B:$B,总表!$A2),INDEX(科学院!E:E,MATCH(总表!$A2,科学院!$B:$B,0)),0) -> 0 | E2: =IF(COUNTIF(科学院!$B:$B,总表!$A2),INDEX(科学院!F:F,MATCH(总表!$A2,科学院!$B:$B,0)),0) -> 0 | F2: =IF(COUNTIF(科学院!$B:$B,总表!$A2),INDEX(科学院!G:G,MATCH(总表!$A2,科学院!$B:$B,0)),0) -> 0 | G2: =IF(COUNTIF(科学院!$B:$B,总表!$A2),INDEX(科学院!H:H,MATCH(总表!$A2,科学院!$B:$B,0)),0) -> 1 | H2: =IF(COUNTIF(科学院!$B:$B,总表!$A2),INDEX(科学院!H:H,MATCH(总表!$A2,科学院!$B:$B,0)),0)+IF(COUNTIF(工程院!$B:$B,总表!$A2),INDEX(工程院!C:C,MATCH(总表!$A2,工程院!$B:$B,0)),0) -> 1 | I2: =IF(COUNTIF(科学院!$B:$B,总表!$A2),INDEX(科学院!I:I,MATCH(总表!$A2,科学院!$B:$B,0)),0)+IF(COUNTIF(工程院!$B:$B,总表!$A2),INDEX(工程院!D:D,MATCH(总表!$A2,工程院!$B:$B,0)),0) -> 1 | J2: =IF(COUNTIF(科学院!$B:$B,总表!$A2),INDEX(科学院!J:J,MATCH(总表!$A2,科学院!$B:$B,0)),0)+IF(COUNTIF(工程院!$B:$B,总表!$A2),INDEX(工程院!E:E,MATCH(总表!$A2,工程院!$B:$B,0)),0) -> 1 | K2: =IF(COUNTIF(科学院!$B:$B,总表!$A2),INDEX(科学院!K:K,MATCH(总表!$A2,科学院!$B:$B,0)),0)+IF(COUNTIF(工程院!$B:$B,总表!$A2),INDEX(工程院!F:F,MATCH(总表!$A2,工程院!$B:$B,0)),0) -> 1 | L2: =IF(COUNTIF(科学院!$B:$B,总表!$A2),INDEX(科学院!L:L,MATCH(总表!$A2,科学院!$B:$B,0)),0)+IF(COUNTIF(工程院!$B:$B,总表!$A2),INDEX(工程院!G:G,MATCH(总表!$A2,工程院!$B:$B,0)),0) -> 1 | M2: =IF(COUNTIF(科学院!$B:$B,总表!$A2),INDEX(科学院!M:M,MATCH(总表!$A2,科学院!$B:$B,0)),0)+IF(COUNTIF(工程院!$B:$B,总表!$A2),INDEX(工程院!H:H,MATCH(总表!$A2,工程院!$B:$B,0)),0) -> 1 | N2: =IF(COUNTIF(科学院!$B:$B,总表!$A2),INDEX(科学院!N:N,MATCH(总表!$A2,科学院!$B:$B,0)),0)+IF(COUNTIF(工程院!$B:$B,总表!$A2),INDEX(工程院!I:I,MATCH(总表!$A2,工程院!$B:$B,0)),0) -> 1 | O2: =IF(COUNTIF(科学院!$B:$B,总表!$A2),INDEX(科学院!O:O,MATCH(总表!$A2,科学院!$B:$B,0)),0)+IF(COUNTIF(工程院!$B:$B,总表!$A2),INDEX(工程院!J:J,MATCH(总表!$A2,工程院!$B:$B,0)),0) -> 1 | P2: =IF(COUNTIF(科学院!$B:$B,总表!$A2),INDEX(科学院!P:P,MATCH(总表!$A2,科学院!$B:$B,0)),0)+IF(COUNTIF(工程院!$B:$B,总表!$A2),INDEX(工程院!K:K,MATCH(总表!$A2,工程院!$B:$B,0)),0) -> 1 | Q2: =IF(COUNTIF(科学院!$B:$B,总表!$A2),INDEX(科学院!Q:Q,MATCH(总表!$A2,科学院!$B:$B,0)),0)+IF(COUNTIF(工程院!$B:$B,总表!$A2),INDEX(工程院!L:L,MATCH(总表!$A2,工程院!$B:$B,0)),0) -> 1 | R2: =IF(COUNTIF(科学院!$B:$B,总表!$A2),INDEX(科学院!R:R,MATCH(总表!$A2,科学院!$B:$B,0)),0)+IF(COUNTIF(工程院!$B:$B,总表!$A2),INDEX(工程院!M:M,MATCH(总表!$A2,工程院!$B:$B,0)),0) -> 1 | S2: =IF(COUNTIF(科学院!$B:$B,总表!$A2),INDEX(科学院!S:S,MATCH(总表!$A2,科学院!$B:$B,0)),0)+IF(COUNTIF(工程院!$B:$B,总表!$A2),INDEX(工程院!N:N,MATCH(总表!$A2,工程院!$B:$B,0)),0) -> 1 | T2: =IF(COUNTIF(科学院!$B:$B,总表!$A2),INDEX(科学院!T:T,MATCH(总表!$A2,科学院!$B:$B,0)),0)+IF(COUNTIF(工程院!$B:$B,总表!$A2),INDEX(工程院!O:O,MATCH(总表!$A2,工程院!$B:$B,0)),0) -> 1 | U2: =IF(COUNTIF(科学院!$B:$B,总表!$A2),INDEX(科学院!U:U,MATCH(总表!$A2,科学院!$B:$B,0)),0)+IF(COUNTIF(工程院!$B:$B,总表!$A2),INDEX(工程院!P:P,MATCH(总表!$A2,工程院!$B:$B,0)),0) -> 1 | V2: =IF(COUNTIF(科学院!$B:$B,总表!$A2),INDEX(科学院!V:V,MATCH(总表!$A2,科学院!$B:$B,0)),0)+IF(COUNTIF(工程院!$B:$B,总表!$A2),INDEX(工程院!Q:Q,MATCH(总表!$A2,工程院!$B:$B,0)),0) -> 1
A3: 安徽大学 | B3: =IF(COUNTIF(科学院!$B:$B,总表!$A3),INDEX(科学院!C:C,MATCH(总表!$A3,科学院!$B:$B,0)),0) -> 0 | C3: =IF(COUNTIF(科学院!$B:$B,总表!$A3),INDEX(科学院!D:D,MATCH(总表!$A3,科学院!$B:$B,0)),0) -> 0 | D3: =IF(COUNTIF(科学院!$B:$B,总表!$A3),INDEX(科学院!E:E,MATCH(总表!$A3,科学院!$B:$B,0)),0) -> 0 | E3: =IF(COUNTIF(科学院!$B:$B,总表!$A3),INDEX(科学院!F:F,MATCH(总表!$A3,科学院!$B:$B,0)),0) -> 0 | F3: =IF(COUNTIF(科学院!$B:$B,总表!$A3),INDEX(科学院!G:G,MATCH(总表!$A3,科学院!$B:$B,0)),0) -> 0 | G3: =IF(COUNTIF(科学院!$B:$B,总表!$A3),INDEX(科学院!H:H,MATCH(总表!$A3,科学院!$B:$B,0)),0) -> 0 | H3: =IF(COUNTIF(科学院!$B:$B,总表!$A3),INDEX(科学院!H:H,MATCH(总表!$A3,科学院!$B:$B,0)),0)+IF(COUNTIF(工程院!$B:$B,总表!$A3),INDEX(工程院!C:C,MATCH(总表!$A3,工程院!$B:$B,0)),0) -> 0 | I3: =IF(COUNTIF(科学院!$B:$B,总表!$A3),INDEX(科学院!I:I,MATCH(总表!$A3,科学院!$B:$B,0)),0)+IF(COUNTIF(工程院!$B:$B,总表!$A3),INDEX(工程院!D:D,MATCH(总表!$A3,工程院!$B:$B,0)),0) -> 1 | J3: =IF(COUNTIF(科学院!$B:$B,总表!$A3),INDEX(科学院!J:J,MATCH(总表!$A3,科学院!$B:$B,0)),0)+IF(COUNTIF(工程院!$B:$B,总表!$A3),INDEX(工程院!E:E,MATCH(总表!$A3,工程院!$B:$B,0)),0) -> 1 | K3: =IF(COUNTIF(科学院!$B:$B,总表!$A3),INDEX(科学院!K:K,MATCH(总表!$A3,科学院!$B:$B,0)),0)+IF(COUNTIF(工程院!$B:$B,总表!$A3),INDEX(工程院!F:F,MATCH(总表!$A3,工程院!$B:$B,0)),0) -> 1 | L3: =IF(COUNTIF(科学院!$B:$B,总表!$A3),INDEX(科学院!L:L,MATCH(总表!$A3,科学院!$B:$B,0)),0)+IF(COUNTIF(工程院!$B:$B,总表!$A3),INDEX(工程院!G:G,MATCH(总表!$A3,工程院!$B:$B,0)),0) -> 1 | M3: =IF(COUNTIF(科学院!$B:$B,总表!$A3),INDEX(科学院!M:M,MATCH(总表!$A3,科学院!$B:$B,0)),0)+IF(COUNTIF(工程院!$B:$B,总表!$A3),INDEX(工程院!H:H,MATCH(总表!$A3,工程院!$B:$B,0)),0) -> 1 | N3: =IF(COUNTIF(科学院!$B:$B,总表!$A3),INDEX(科学院!N:N,MATCH(总表!$A3,科学院!$B:$B,0)),0)+IF(COUNTIF(工程院!$B:$B,总表!$A3),INDEX(工程院!I:I,MATCH(总表!$A3,工程院!$B:$B,0)),0) -> 1 | O3: =IF(COUNTIF(科学院!$B:$B,总表!$A3),INDEX(科学院!O:O,MATCH(总表!$A3,科学院!$B:$B,0)),0)+IF(COUNTIF(工程院!$B:$B,总表!$A3),INDEX(工程院!J:J,MATCH(总表!$A3,工程院!$B:$B,0)),0) -> 2 | P3: =IF(COUNTIF(科学院!$B:$B,总表!$A3),INDEX(科学院!P:P,MATCH(总表!$A3,科学院!$B:$B,0)),0)+IF(COUNTIF(工程院!$B:$B,总表!$A3),INDEX(工程院!K:K,MATCH(总表!$A3,工程院!$B:$B,0)),0) -> 2 | Q3: =IF(COUNTIF(科学院!$B:$B,总表!$A3),INDEX(科学院!Q:Q,MATCH(总表!$A3,科学院!$B:$B,0)),0)+IF(COUNTIF(工程院!$B:$B,总表!$A3),INDEX(工程院!L:L,MATCH(总表!$A3,工程院!$B:$B,0)),0) -> 2 | R3: =IF(COUNTIF(科学院!$B:$B,总表!$A3),INDEX(科学院!R:R,MATCH(总表!$A3,科学院!$B:$B,0)),0)+IF(COUNTIF(工程院!$B:$B,总表!$A3),INDEX(工程院!M:M,MATCH(总表!$A3,工程院!$B:$B,0)),0) -> 2 | S3: =IF(COUNTIF(科学院!$B:$B,总表!$A3),INDEX(科学院!S:S,MATCH(总表!$A3,科学院!$B:$B,0)),0)+IF(COUNTIF(工程院!$B:$B,总表!$A3),INDEX(工程院!N:N,MATCH(总表!$A3,工程院!$B:$B,0)),0) -> 2 | T3: =IF(COUNTIF(科学院!$B:$B,总表!$A3),INDEX(科学院!T:T,MATCH(总表!$A3,科学院!$B:$B,0)),0)+IF(COUNTIF(工程院!$B:$B,总表!$A3),INDEX(工程院!O:O,MATCH(总表!$A3,工程院!$B:$B,0)),0) -> 2 | U3: =IF(COUNTIF(科学院!$B:$B,总表!$A3),INDEX(科学院!U:U,MATCH(总表!$A3,科学院!$B:$B,0)),0)+IF(COUNTIF(工程院!$B:$B,总表!$A3),INDEX(工程院!P:P,MATCH(总表!$A3,工程院!$B:$B,0)),0) -> 2 | V3: =IF(COUNTIF(科学院!$B:$B,总表!$A3),INDEX(科学院!V:V,MATCH(总表!$A3,科学院!$B:$B,0)),0)+IF(COUNTIF(工程院!$B:$B,总表!$A3),INDEX(工程院!Q:Q,MATCH(总表!$A3,工程院!$B:$B,0)),0) -> 2
A4: 安徽教育学院 | B4: =IF(COUNTIF(科学院!$B:$B,总表!$A4),INDEX(科学院!C:C,MATCH(总表!$A4,科学院!$B:$B,0)),0) -> 0 | C4: =IF(COUNTIF(科学院!$B:$B,总表!$A4),INDEX(科学院!D:D,MATCH(总表!$A4,科学院!$B:$B,0)),0) -> 0 | D4: =IF(COUNTIF(科学院!$B:$B,总表!$A4),INDEX(科学院!E:E,MATCH(总表!$A4,科学院!$B:$B,0)),0) -> 0 | E4: =IF(COUNTIF(科学院!$B:$B,总表!$A4),INDEX(科学院!F:F,MATCH(总表!$A4,科学院!$B:$B,0)),0) -> 0 | F4: =IF(COUNTIF(科学院!$B:$B,总表!$A4),INDEX(科学院!G:G,MATCH(总表!$A4,科学院!$B:$B,0)),0) -> 0 | G4: =IF(COUNTIF(科学院!$B:$B,总表!$A4),INDEX(科学院!H:H,MATCH(总表!$A4,科学院!$B:$B,0)),0) -> 0 | H4: =IF(COUNTIF(科学院!$B:$B,总表!$A4),INDEX(科学院!H:H,MATCH(总表!$A4,科学院!$B:$B,0)),0)+IF(COUNTIF(工程院!$B:$B,总表!$A4),INDEX(工程院!C:C,MATCH(总表!$A4,工程院!$B:$B,0)),0) -> 0 | I4: =IF(COUNTIF(科学院!$B:$B,总表!$A4),INDEX(科学院!I:I,MATCH(总表!$A4,科学院!$B:$B,0)),0)+IF(COUNTIF(工程院!$B:$B,总表!$A4),INDEX(工程院!D:D,MATCH(总表!$A4,工程院!$B:$B,0)),0) -> 0 | J4: =IF(COUNTIF(科学院!$B:$B,总表!$A4),INDEX(科学院!J:J,MATCH(总表!$A4,科学院!$B:$B,0)),0)+IF(COUNTIF(工程院!$B:$B,总表!$A4),INDEX(工程院!E:E,MATCH(总表!$A4,工程院!$B:$B,0)),0) -> 0 | K4: =IF(COUNTIF(科学院!$B:$B,总表!$A4),INDEX(科学院!K:K,MATCH(总表!$A4,科学院!$B:$B,0)),0)+IF(COUNTIF(工程院!$B:$B,总表!$A4),INDEX(工程院!F:F,MATCH(总表!$A4,工程院!$B:$B,0)),0) -> 0 | L4: =IF(COUNTIF(科学院!$B:$B,总表!$A4),INDEX(科学院!L:L,MATCH(总表!$A4,科学院!$B:$B,0)),0)+IF(COUNTIF(工程院!$B:$B,总表!$A4),INDEX(工程院!G:G,MATCH(总表!$A4,工程院!$B:$B,0)),0) -> 0 | M4: =IF(COUNTIF(科学院!$B:$B,总表!$A4),INDEX(科学院!M:M,MATCH(总表!$A4,科学院!$B:$B,0)),0)+IF(COUNTIF(工程院!$B:$B,总表!$A4),INDEX(工程院!H:H,MATCH(总表!$A4,工程院!$B:$B,0)),0) -> 0 | N4: =IF(COUNTIF(科学院!$B:$B,总表!$A4),INDEX(科学院!N:N,MATCH(总表!$A4,科学院!$B:$B,0)),0)+IF(COUNTIF(工程院!$B:$B,总表!$A4),INDEX(工程院!I:I,MATCH(总表!$A4,工程院!$B:$B,0)),0) -> 0 | O4: =IF(COUNTIF(科学院!$B:$B,总表!$A4),INDEX(科学院!O:O,MATCH(总表!$A4,科学院!$B:$B,0)),0)+IF(COUNTIF(工程院!$B:$B,总表!$A4),INDEX(工程院!J:J,MATCH(总表!$A4,工程院!$B:$B,0)),0) -> 0 | P4: =IF(COUNTIF(科学院!$B:$B,总表!$A4),INDEX(科学院!P:P,MATCH(总表!$A4,科学院!$B:$B,0)),0)+IF(COUNTIF(工程院!$B:$B,总表!$A4),INDEX(工程院!K:K,MATCH(总表!$A4,工程院!$B:$B,0)),0) -> 0 | Q4: =IF(COUNTIF(科学院!$B:$B,总表!$A4),INDEX(科学院!Q:Q,MATCH(总表!$A4,科学院!$B:$B,0)),0)+IF(COUNTIF(工程院!$B:$B,总表!$A4),INDEX(工程院!L:L,MATCH(总表!$A4,工程院!$B:$B,0)),0) -> 1 | R4: =IF(COUNTIF(科学院!$B:$B,总表!$A4),INDEX(科学院!R:R,MATCH(总表!$A4,科学院!$B:$B,0)),0)+IF(COUNTIF(工程院!$B:$B,总表!$A4),INDEX(工程院!M:M,MATCH(总表!$A4,工程院!$B:$B,0)),0) -> 1 | S4: =IF(COUNTIF(科学院!$B:$B,总表!$A4),INDEX(科学院!S:S,MATCH(总表!$A4,科学院!$B:$B,0)),0)+IF(COUNTIF(工程院!$B:$B,总表!$A4),INDEX(工程院!N:N,MATCH(总表!$A4,工程院!$B:$B,0)),0) -> 1 | T4: =IF(COUNTIF(科学院!$B:$B,总表!$A4),INDEX(科学院!T:T,MATCH(总表!$A4,科学院!$B:$B,0)),0)+IF(COUNTIF(工程院!$B:$B,总表!$A4),INDEX(工程院!O:O,MATCH(总表!$A4,工程院!$B:$B,0)),0) -> 1 | U4: =IF(COUNTIF(科学院!$B:$B,总表!$A4),INDEX(科学院!U:U,MATCH(总表!$A4,科学院!$B:$B,0)),0)+IF(COUNTIF(工程院!$B:$B,总表!$A4),INDEX(工程院!P:P,MATCH(总表!$A4,工程院!$B:$B,0)),0) -> 1 | V4: =IF(COUNTIF(科学院!$B:$B,总表!$A4),INDEX(科学院!V:V,MATCH(总表!$A4,科学院!$B:$B,0)),0)+IF(COUNTIF(工程院!$B:$B,总表!$A4),INDEX(工程院!Q:Q,MATCH(总表!$A4,工程院!$B:$B,0)),0) -> 1
A5: 安徽农学院 | B5: =IF(COUNTIF(科学院!$B:$B,总表!$A5),INDEX(科学院!C:C,MATCH(总表!$A5,科学院!$B:$B,0)),0) -> 0 | C5: =IF(COUNTIF(科学院!$B:$B,总表!$A5),INDEX(科学院!D:D,MATCH(总表!$A5,科学院!$B:$B,0)),0) -> 0 | D5: =IF(COUNTIF(科学院!$B:$B,总表!$A5),INDEX(科学院!E:E,MATCH(总表!$A5,科学院!$B:$B,0)),0) -> 0 | E5: =IF(COUNTIF(科学院!$B:$B,总表!$A5),INDEX(科学院!F:F,MATCH(总表!$A5,科学院!$B:$B,0)),0) -> 0 | F5: =IF(COUNTIF(科学院!$B:$B,总表!$A5),INDEX(科学院!G:G,MATCH(总表!$A5,科学院!$B:$B,0)),0) -> 0 | G5: =IF(COUNTIF(科学院!$B:$B,总表!$A5),INDEX(科学院!H:H,MATCH(总表!$A5,科学院!$B:$B,0)),0) -> 0 | H5: =IF(COUNTIF(科学院!$B:$B,总表!$A5),INDEX(科学院!H:H,MATCH(总表!$A5,科学院!$B:$B,0)),0)+IF(COUNTIF(工程院!$B:$B,总表!$A5),INDEX(工程院!C:C,MATCH(总表!$A5,工程院!$B:$B,0)),0) -> 0 | I5: =IF(COUNTIF(科学院!$B:$B,总表!$A5),INDEX(科学院!I:I,MATCH(总表!$A5,科学院!$B:$B,0)),0)+IF(COUNTIF(工程院!$B:$B,总表!$A5),INDEX(工程院!D:D,MATCH(总表!$A5,工程院!$B:$B,0)),0) -> 0 | J5: =IF(COUNTIF(科学院!$B:$B,总表!$A5),INDEX(科学院!J:J,MATCH(总表!$A5,科学院!$B:$B,0)),0)+IF(COUNTIF(工程院!$B:$B,总表!$A5),INDEX(工程院!E:E,MATCH(总表!$A5,工程院!$B:$B,0)),0) -> 0 | K5: =IF(COUNTIF(科学院!$B:$B,总表!$A5),INDEX(科学院!K:K,MATCH(总表!$A5,科学院!$B:$B,0)),0)+IF(COUNTIF(工程院!$B:$B,总表!$A5),INDEX(工程院!F:F,MATCH(总表!$A5,工程院!$B:$B,0)),0) -> 0 | L5: =IF(COUNTIF(科学院!$B:$B,总表!$A5),INDEX(科学院!L:L,MATCH(总表!$A5,科学院!$B:$B,0)),0)+IF(COUNTIF(工程院!$B:$B,总表!$A5),INDEX(工程院!G:G,MATCH(总表!$A5,工程院!$B:$B,0)),0) -> 1 | M5: =IF(COUNTIF(科学院!$B:$B,总表!$A5),INDEX(科学院!M:M,MATCH(总表!$A5,科学院!$B:$B,0)),0)+IF(COUNTIF(工程院!$B:$B,总表!$A5),INDEX(工程院!H:H,MATCH(总表!$A5,工程院!$B:$B,0)),0) -> 1 | N5: =IF(COUNTIF(科学院!$B:$B,总表!$A5),INDEX(科学院!N:N,MATCH(总表!$A5,科学院!$B:$B,0)),0)+IF(COUNTIF(工程院!$B:$B,总表!$A5),INDEX(工程院!I:I,MATCH(总表!$A5,工程院!$B:$B,0)),0) -> 1 | O5: =IF(COUNTIF(科学院!$B:$B,总表!$A5),INDEX(科学院!O:O,MATCH(总表!$A5,科学院!$B:$B,0)),0)+IF(COUNTIF(工程院!$B:$B,总表!$A5),INDEX(工程院!J:J,MATCH(总表!$A5,工程院!$B:$B,0)),0) -> 1 | P5: =IF(COUNTIF(科学院!$B:$B,总表!$A5),INDEX(科学院!P:P,MATCH(总表!$A5,科学院!$B:$B,0)),0)+IF(COUNTIF(工程院!$B:$B,总表!$A5),INDEX(工程院!K:K,MATCH(总表!$A5,工程院!$B:$B,0)),0) -> 1 | Q5: =IF(COUNTIF(科学院!$B:$B,总表!$A5),INDEX(科学院!Q:Q,MATCH(总表!$A5,科学院!$B:$B,0)),0)+IF(COUNTIF(工程院!$B:$B,总表!$A5),INDEX(工程院!L:L,MATCH(总表!$A5,工程院!$B:$B,0)),0) -> 1 | R5: =IF(COUNTIF(科学院!$B:$B,总表!$A5),INDEX(科学院!R:R,MATCH(总表!$A5,科学院!$B:$B,0)),0)+IF(COUNTIF(工程院!$B:$B,总表!$A5),INDEX(工程院!M:M,MATCH(总表!$A5,工程院!$B:$B,0)),0) -> 1 | S5: =IF(COUNTIF(科学院!$B:$B,总表!$A5),INDEX(科学院!S:S,MATCH(总表!$A5,科学院!$B:$B,0)),0)+IF(COUNTIF(工程院!$B:$B,总表!$A5),INDEX(工程院!N:N,MATCH(总表!$A5,工程院!$B:$B,0)),0) -> 1 | T5: =IF(COUNTIF(科学院!$B:$B,总表!$A5),INDEX(科学院!T:T,MATCH(总表!$A5,科学院!$B:$B,0)),0)+IF(COUNTIF(工程院!$B:$B,总表!$A5),INDEX(工程院!O:O,MATCH(总表!$A5,工程院!$B:$B,0)),0) -> 1 | U5: =IF(COUNTIF(科学院!$B:$B,总表!$A5),INDEX(科学院!U:U,MATCH(总表!$A5,科学院!$B:$B,0)),0)+IF(COUNTIF(工程院!$B:$B,总表!$A5),INDEX(工程院!P:P,MATCH(总表!$A5,工程院!$B:$B,0)),0) -> 1 | V5: =IF(COUNTIF(科学院!$B:$B,总表!$A5),INDEX(科学院!V:V,MATCH(总表!$A5,科学院!$B:$B,0)),0)+IF(COUNTIF(工程院!$B:$B,总表!$A5),INDEX(工程院!Q:Q,MATCH(总表!$A5,工程院!$B:$B,0)),0) -> 1
A6: 安徽农业大学 | B6: =IF(COUNTIF(科学院!$B:$B,总表!$A6),INDEX(科学院!C:C,MATCH(总表!$A6,科学院!$B:$B,0)),0) -> 0 | C6: =IF(COUNTIF(科学院!$B:$B,总表!$A6),INDEX(科学院!D:D,MATCH(总表!$A6,科学院!$B:$B,0)),0) -> 0 | D6: =IF(COUNTIF(科学院!$B:$B,总表!$A6),INDEX(科学院!E:E,MATCH(总表!$A6,科学院!$B:$B,0)),0) -> 0 | E6: =IF(COUNTIF(科学院!$B:$B,总表!$A6),INDEX(科学院!F:F,MATCH(总表!$A6,科学院!$B:$B,0)),0) -> 0 | F6: =IF(COUNTIF(科学院!$B:$B,总表!$A6),INDEX(科学院!G:G,MATCH(总表!$A6,科学院!$B:$B,0)),0) -> 0 | G6: =IF(COUNTIF(科学院!$B:$B,总表!$A6),INDEX(科学院!H:H,MATCH(总表!$A6,科学院!$B:$B,0)),0) -> 0 | H6: =IF(COUNTIF(科学院!$B:$B,总表!$A6),INDEX(科学院!H:H,MATCH(总表!$A6,科学院!$B:$B,0)),0)+IF(COUNTIF(工程院!$B:$B,总表!$A6),INDEX(工程院!C:C,MATCH(总表!$A6,工程院!$B:$B,0)),0) -> 0 | I6: =IF(COUNTIF(科学院!$B:$B,总表!$A6),INDEX(科学院!I:I,MATCH(总表!$A6,科学院!$B:$B,0)),0)+IF(COUNTIF(工程院!$B:$B,总表!$A6),INDEX(工程院!D:D,MATCH(总表!$A6,工程院!$B:$B,0)),0) -> 0 | J6: =IF(COUNTIF(科学院!$B:$B,总表!$A6),INDEX(科学院!J:J,MATCH(总表!$A6,科学院!$B:$B,0)),0)+IF(COUNTIF(工程院!$B:$B,总表!$A6),INDEX(工程院!E:E,MATCH(总表!$A6,工程院!$B:$B,0)),0) -> 0 | K6: =IF(COUNTIF(科学院!$B:$B,总表!$A6),INDEX(科学院!K:K,MATCH(总表!$A6,科学院!$B:$B,0)),0)+IF(COUNTIF(工程院!$B:$B,总表!$A6),INDEX(工程院!F:F,MATCH(总表!$A6,工程院!$B:$B,0)),0) -> 0 | L6: =IF(COUNTIF(科学院!$B:$B,总表!$A6),INDEX(科学院!L:L,MATCH(总表!$A6,科学院!$B:$B,0)),0)+IF(COUNTIF(工程院!$B:$B,总表!$A6),INDEX(工程院!G:G,MATCH(总表!$A6,工程院!$B:$B,0)),0) -> 0 | M6: =IF(COUNTIF(科学院!$B:$B,总表!$A6),INDEX(科学院!M:M,MATCH(总表!$A6,科学院!$B:$B,0)),0)+IF(COUNTIF(工程院!$B:$B,总表!$A6),INDEX(工程院!H:H,MATCH(总表!$A6,工程院!$B:$B,0)),0) -> 0 | N6: =IF(COUNTIF(科学院!$B:$B,总表!$A6),INDEX(科学院!N:N,MATCH(总表!$A6,科学院!$B:$B,0)),0)+IF(COUNTIF(工程院!$B:$B,总表!$A6),INDEX(工程院!I:I,MATCH(总表!$A6,工程院!$B:$B,0)),0) -> 1 | O6: =IF(COUNTIF(科学院!$B:$B,总表!$A6),INDEX(科学院!O:O,MATCH(总表!$A6,科学院!$B:$B,0)),0)+IF(COUNTIF(工程院!$B:$B,总表!$A6),INDEX(工程院!J:J,MATCH(总表!$A6,工程院!$B:$B,0)),0) -> 1 | P6: =IF(COUNTIF(科学院!$B:$B,总表!$A6),INDEX(科学院!P:P,MATCH(总表!$A6,科学院!$B:$B,0)),0)+IF(COUNTIF(工程院!$B:$B,总表!$A6),INDEX(工程院!K:K,MATCH(总表!$A6,工程院!$B:$B,0)),0) -> 1 | Q6: =IF(COUNTIF(科学院!$B:$B,总表!$A6),INDEX(科学院!Q:Q,MATCH(总表!$A6,科学院!$B:$B,0)),0)+IF(COUNTIF(工程院!$B:$B,总表!$A6),INDEX(工程院!L:L,MATCH(总表!$A6,工程院!$B:$B,0)),0) -> 1 | R6: =IF(COUNTIF(科学院!$B:$B,总表!$A6),INDEX(科学院!R:R,MATCH(总表!$A6,科学院!$B:$B,0)),0)+IF(COUNTIF(工程院!$B:$B,总表!$A6),INDEX(工程院!M:M,MATCH(总表!$A6,工程院!$B:$B,0)),0) -> 1 | S6: =IF(COUNTIF(科学院!$B:$B,总表!$A6),INDEX(科学院!S:S,MATCH(总表!$A6,科学院!$B:$B,0)),0)+IF(COUNTIF(工程院!$B:$B,总表!$A6),INDEX(工程院!N:N,MATCH(总表!$A6,工程院!$B:$B,0)),0) -> 1 | T6: =IF(COUNTIF(科学院!$B:$B,总表!$A6),INDEX(科学院!T:T,MATCH(总表!$A6,科学院!$B:$B,0)),0)+IF(COUNTIF(工程院!$B:$B,总表!$A6),INDEX(工程院!O:O,MATCH(总表!$A6,工程院!$B:$B,0)),0) -> 1 | U6: =IF(COUNTIF(科学院!$B:$B,总表!$A6),INDEX(科学院!U:U,MATCH(总表!$A6,科学院!$B:$B,0)),0)+IF(COUNTIF(工程院!$B:$B,总表!$A6),INDEX(工程院!P:P,MATCH(总表!$A6,工程院!$B:$B,0)),0) -> 1 | V6: =IF(COUNTIF(科学院!$B:$B,总表!$A6),INDEX(科学院!V:V,MATCH(总表!$A6,科学院!$B:$B,0)),0)+IF(COUNTIF(工程院!$B:$B,总表!$A6),INDEX(工程院!Q:Q,MATCH(总表!$A6,工程院!$B:$B,0)),0) -> 1
A7: 安徽师范大学 | B7: =IF(COUNTIF(科学院!$B:$B,总表!$A7),INDEX(科学院!C:C,MATCH(总表!$A7,科学院!$B:$B,0)),0) -> 0 | C7: =IF(COUNTIF(科学院!$B:$B,总表!$A7),INDEX(科学院!D:D,MATCH(总表!$A7,科学院!$B:$B,0)),0) -> 0 | D7: =IF(COUNTIF(科学院!$B:$B,总表!$A7),INDEX(科学院!E:E,MATCH(总表!$A7,科学院!$B:$B,0)),0) -> 0 | E7: =IF(COUNTIF(科学院!$B:$B,总表!$A7),INDEX(科学院!F:F,MATCH(总表!$A7,科学院!$B:$B,0)),0) -> 0 | F7: =IF(COUNTIF(科学院!$B:$B,总表!$A7),INDEX(科学院!G:G,MATCH(总表!$A7,科学院!$B:$B,0)),0) -> 0 | G7: =IF(COUNTIF(科学院!$B:$B,总表!$A7),INDEX(科学院!H:H,MATCH(总表!$A7,科学院!$B:$B,0)),0) -> 0 | H7: =IF(COUNTIF(科学院!$B:$B,总表!$A7),INDEX(科学院!H:H,MATCH(总表!$A7,科学院!$B:$B,0)),0)+IF(COUNTIF(工程院!$B:$B,总表!$A7),INDEX(工程院!C:C,MATCH(总表!$A7,工程院!$B:$B,0)),0) -> 0 | I7: =IF(COUNTIF(科学院!$B:$B,总表!$A7),INDEX(科学院!I:I,MATCH(总表!$A7,科学院!$B:$B,0)),0)+IF(COUNTIF(工程院!$B:$B,总表!$A7),INDEX(工程院!D:D,MATCH(总表!$A7,工程院!$B:$B,0)),0) -> 0 | J7: =IF(COUNTIF(科学院!$B:$B,总表!$A7),INDEX(科学院!J:J,MATCH(总表!$A7,科学院!$B:$B,0)),0)+IF(COUNTIF(工程院!$B:$B,总表!$A7),INDEX(工程院!E:E,MATCH(总表!$A7,工程院!$B:$B,0)),0) -> 0 | K7: =IF(COUNTIF(科学院!$B:$B,总表!$A7),INDEX(科学院!K:K,MATCH(总表!$A7,科学院!$B:$B,0)),0)+IF(COUNTIF(工程院!$B:$B,总表!$A7),INDEX(工程院!F:F,MATCH(总表!$A7,工程院!$B:$B,0)),0) -> 0 | L7: =IF(COUNTIF(科学院!$B:$B,总表!$A7),INDEX(科学院!L:L,MATCH(总表!$A7,科学院!$B:$B,0)),0)+IF(COUNTIF(工程院!$B:$B,总表!$A7),INDEX(工程院!G:G,MATCH(总表!$A7,工程院!$B:$B,0)),0) -> 0 | M7: =IF(COUNTIF(科学院!$B:$B,总表!$A7),INDEX(科学院!M:M,MATCH(总表!$A7,科学院!$B:$B,0)),0)+IF(COUNTIF(工程院!$B:$B,总表!$A7),INDEX(工程院!H:H,MATCH(总表!$A7,工程院!$B:$B,0)),0) -> 0 | N7: =IF(COUNTIF(科学院!$B:$B,总表!$A7),INDEX(科学院!N:N,MATCH(总表!$A7,科学院!$B:$B,0)),0)+IF(COUNTIF(工程院!$B:$B,总表!$A7),INDEX(工程院!I:I,MATCH(总表!$A7,工程院!$B:$B,0)),0) -> 0 | O7: =IF(COUNTIF(科学院!$B:$B,总表!$A7),INDEX(科学院!O:O,MATCH(总表!$A7,科学院!$B:$B,0)),0)+IF(COUNTIF(工程院!$B:$B,总表!$A7),INDEX(工程院!J:J,MATCH(总表!$A7,工程院!$B:$B,0)),0) -> 0 | P7: =IF(COUNTIF(科学院!$B:$B,总表!$A7),INDEX(科学院!P:P,MATCH(总表!$A7,科学院!$B:$B,0)),0)+IF(COUNTIF(工程院!$B:$B,总表!$A7),INDEX(工程院!K:K,MATCH(总表!$A7,工程院!$B:$B,0)),0) -> 0 | Q7: =IF(COUNTIF(科学院!$B:$B,总表!$A7),INDEX(科学院!Q:Q,MATCH(总表!$A7,科学院!$B:$B,0)),0)+IF(COUNTIF(工程院!$B:$B,总表!$A7),INDEX(工程院!L:L,MATCH(总表!$A7,工程院!$B:$B,0)),0) -> 1 | R7: =IF(COUNTIF(科学院!$B:$B,总表!$A7),INDEX(科学院!R:R,MATCH(总表!$A7,科学院!$B:$B,0)),0)+IF(COUNTIF(工程院!$B:$B,总表!$A7),INDEX(工程院!M:M,MATCH(总表!$A7,工程院!$B:$B,0)),0) -> 3 | S7: =IF(COUNTIF(科学院!$B:$B,总表!$A7),INDEX(科学院!S:S,MATCH(总表!$A7,科学院!$B:$B,0)),0)+IF(COUNTIF(工程院!$B:$B,总表!$A7),INDEX(工程院!N:N,MATCH(总表!$A7,工程院!$B:$B,0)),0) -> 4 | T7: =IF(COUNTIF(科学院!$B:$B,总表!$A7),INDEX(科学院!T:T,MATCH(总表!$A7,科学院!$B:$B,0)),0)+IF(COUNTIF(工程院!$B:$B,总表!$A7),INDEX(工程院!O:O,MATCH(总表!$A7,工程院!$B:$B,0)),0) -> 4 | U7: =IF(COUNTIF(科学院!$B:$B,总表!$A7),INDEX(科学院!U:U,MATCH(总表!$A7,科学院!$B:$B,0)),0)+IF(COUNTIF(工程院!$B:$B,总表!$A7),INDEX(工程院!P:P,MATCH(总表!$A7,工程院!$B:$B,0)),0) -> 4 | V7: =IF(COUNTIF(科学院!$B:$B,总表!$A7),INDEX(科学院!V:V,MATCH(总表!$A7,科学院!$B:$B,0)),0)+IF(COUNTIF(工程院!$B:$B,总表!$A7),INDEX(工程院!Q:Q,MATCH(总表!$A7,工程院!$B:$B,0)),0) -> 4
A8: 白求恩医科大学 | B8: =IF(COUNTIF(科学院!$B:$B,总表!$A8),INDEX(科学院!C:C,MATCH(总表!$A8,科学院!$B:$B,0)),0) -> 0 | C8: =IF(COUNTIF(科学院!$B:$B,总表!$A8),INDEX(科学院!D:D,MATCH(总表!$A8,科学院!$B:$B,0)),0) -> 0 | D8: =IF(COUNTIF(科学院!$B:$B,总表!$A8),INDEX(科学院!E:E,MATCH(总表!$A8,科学院!$B:$B,0)),0) -> 0 | E8: =IF(COUNTIF(科学院!$B:$B,总表!$A8),INDEX(科学院!F:F,MATCH(总表!$A8,科学院!$B:$B,0)),0) -> 0 | F8: =IF(COUNTIF(科学院!$B:$B,总表!$A8),INDEX(科学院!G:G,MATCH(总表!$A8,科学院!$B:$B,0)),0) -> 0 | G8: =IF(COUNTIF(科学院!$B:$B,总表!$A8),INDEX(科学院!H:H,MATCH(总表!$A8,科学院!$B:$B,0)),0) -> 0 | H8: =IF(COUNTIF(科学院!$B:$B,总表!$A8),INDEX(科学院!H:H,MATCH(总表!$A8,科学院!$B:$B,0)),0)+IF(COUNTIF(工程院!$B:$B,总表!$A8),INDEX(工程院!C:C,MATCH(总表!$A8,工程院!$B:$B,0)),0) -> 0 | I8: =IF(COUNTIF(科学院!$B:$B,总表!$A8),INDEX(科学院!I:I,MATCH(总表!$A8,科学院!$B:$B,0)),0)+IF(COUNTIF(工程院!$B:$B,总表!$A8),INDEX(工程院!D:D,MATCH(总表!$A8,工程院!$B:$B,0)),0) -> 0 | J8: =IF(COUNTIF(科学院!$B:$B,总表!$A8),INDEX(科学院!J:J,MATCH(总表!$A8,科学院!$B:$B,0)),0)+IF(COUNTIF(工程院!$B:$B,总表!$A8),INDEX(工程院!E:E,MATCH(总表!$A8,工程院!$B:$B,0)),0) -> 0 | K8: =IF(COUNTIF(科学院!$B:$B,总表!$A8),INDEX(科学院!K:K,MATCH(总表!$A8,科学院!$B:$B,0)),0)+IF(COUNTIF(工程院!$B:$B,总表!$A8),INDEX(工程院!F:F,MATCH(总表!$A8,工程院!$B:$B,0)),0) -> 0 | L8: =IF(COUNTIF(科学院!$B:$B,总表!$A8),INDEX(科学院!L:L,MATCH(总表!$A8,科学院!$B:$B,0)),0)+IF(COUNTIF(工程院!$B:$B,总表!$A8),INDEX(工程院!G:G,MATCH(总表!$A8,工程院!$B:$B,0)),0) -> 0 | M8: =IF(COUNTIF(科学院!$B:$B,总表!$A8),INDEX(科学院!M:M,MATCH(总表!$A8,科学院!$B:$B,0)),0)+IF(COUNTIF(工程院!$B:$B,总表!$A8),INDEX(工程院!H:H,MATCH(总表!$A8,工程院!$B:$B,0)),0) -> 0 | N8: =IF(COUNTIF(科学院!$B:$B,总表!$A8),INDEX(科学院!N:N,MATCH(总表!$A8,科学院!$B:$B,0)),0)+IF(COUNTIF(工程院!$B:$B,总表!$A8),INDEX(工程院!I:I,MATCH(总表!$A8,工程院!$B:$B,0)),0) -> 0 | O8: =IF(COUNTIF(科学院!$B:$B,总表!$A8),INDEX(科学院!O:O,MATCH(总表!$A8,科学院!$B:$B,0)),0)+IF(COUNTIF(工程院!$B:$B,总表!$A8),INDEX(工程院!J:J,MATCH(总表!$A8,工程院!$B:$B,0)),0) -> 0 | P8: =IF(COUNTIF(科学院!$B:$B,总表!$A8),INDEX(科学院!P:P,MATCH(总表!$A8,科学院!$B:$B,0)),0)+IF(COUNTIF(工程院!$B:$B,总表!$A8),INDEX(工程院!K:K,MATCH(总表!$A8,工程院!$B:$B,0)),0) -> 0 | Q8: =IF(COUNTIF(科学院!$B:$B,总表!$A8),INDEX(科学院!Q:Q,MATCH(总表!$A8,科学院!$B:$B,0)),0)+IF(COUNTIF(工程院!$B:$B,总表!$A8),INDEX(工程院!L:L,MATCH(总表!$A8,工程院!$B:$B,0)),0) -> 1 | R8: =IF(COUNTIF(科学院!$B:$B,总表!$A8),INDEX(科学院!R:R,MATCH(总表!$A8,科学院!$B:$B,0)),0)+IF(COUNTIF(工程院!$B:$B,总表!$A8),INDEX(工程院!M:M,MATCH(总表!$A8,工程院!$B:$B,0)),0) -> 3 | S8: =IF(COUNTIF(科学院!$B:$B,总表!$A8),INDEX(科学院!S:S,MATCH(总表!$A8,科学院!$B:$B,0)),0)+IF(COUNTIF(工程院!$B:$B,总表!$A8),INDEX(工程院!N:N,MATCH(总表!$A8,工程院!$B:$B,0)),0) -> 3 | T8: =IF(COUNTIF(科学院!$B:$B,总表!$A8),INDEX(科学院!T:T,MATCH(总表!$A8,科学院!$B:$B,0)),0)+IF(COUNTIF(工程院!$B:$B,总表!$A8),INDEX(工程院!O:O,MATCH(总表!$A8,工程院!$B:$B,0)),0) -> 3 | U8: =IF(COUNTIF(科学院!$B:$B,总表!$A8),INDEX(科学院!U:U,MATCH(总表!$A8,科学院!$B:$B,0)),0)+IF(COUNTIF(工程院!$B:$B,总表!$A8),INDEX(工程院!P:P,MATCH(总表!$A8,工程院!$B:$B,0)),0) -> 4 | V8: =IF(COUNTIF(科学院!$B:$B,总表!$A8),INDEX(科学院!V:V,MATCH(总表!$A8,科学院!$B:$B,0)),0)+IF(COUNTIF(工程院!$B:$B,总表!$A8),INDEX(工程院!Q:Q,MATCH(总表!$A8,工程院!$B:$B,0)),0) -> 4
A9: 蚌埠医学院 | B9: =IF(COUNTIF(科学院!$B:$B,总表!$A9),INDEX(科学院!C:C,MATCH(总表!$A9,科学院!$B:$B,0)),0) -> 0 | C9: =IF(COUNTIF(科学院!$B:$B,总表!$A9),INDEX(科学院!D:D,MATCH(总表!$A9,科学院!$B:$B,0)),0) -> 0 | D9: =IF(COUNTIF(科学院!$B:$B,总表!$A9),INDEX(科学院!E:E,MATCH(总表!$A9,科学院!$B:$B,0)),0) -> 0 | E9: =IF(COUNTIF(科学院!$B:$B,总表!$A9),INDEX(科学院!F:F,MATCH(总表!$A9,科学院!$B:$B,0)),0) -> 0 | F9: =IF(COUNTIF(科学院!$B:$B,总表!$A9),INDEX(科学院!G:G,MATCH(总表!$A9,科学院!$B:$B,0)),0) -> 0 | G9: =IF(COUNTIF(科学院!$B:$B,总表!$A9),INDEX(科学院!H:H,MATCH(总表!$A9,科学院!$B:$B,0)),0) -> 0 | H9: =IF(COUNTIF(科学院!$B:$B,总表!$A9),INDEX(科学院!H:H,MATCH(总表!$A9,科学院!$B:$B,0)),0)+IF(COUNTIF(工程院!$B:$B,总表!$A9),INDEX(工程院!C:C,MATCH(总表!$A9,工程院!$B:$B,0)),0) -> 0 | I9: =IF(COUNTIF(科学院!$B:$B,总表!$A9),INDEX(科学院!I:I,MATCH(总表!$A9,科学院!$B:$B,0)),0)+IF(COUNTIF(工程院!$B:$B,总表!$A9),INDEX(工程院!D:D,MATCH(总表!$A9,工程院!$B:$B,0)),0) -> 0 | J9: =IF(COUNTIF(科学院!$B:$B,总表!$A9),INDEX(科学院!J:J,MATCH(总表!$A9,科学院!$B:$B,0)),0)+IF(COUNTIF(工程院!$B:$B,总表!$A9),INDEX(工程院!E:E,MATCH(总表!$A9,工程院!$B:$B,0)),0) -> 0 | K9: =IF(COUNTIF(科学院!$B:$B,总表!$A9),INDEX(科学院!K:K,MATCH(总表!$A9,科学院!$B:$B,0)),0)+IF(COUNTIF(工程院!$B:$B,总表!$A9),INDEX(工程院!F:F,MATCH(总表!$A9,工程院!$B:$B,0)),0) -> 0 | L9: =IF(COUNTIF(科学院!$B:$B,总表!$A9),INDEX(科学院!L:L,MATCH(总表!$A9,科学院!$B:$B,0)),0)+IF(COUNTIF(工程院!$B:$B,总表!$A9),INDEX(工程院!G:G,MATCH(总表!$A9,工程院!$B:$B,0)),0) -> 0 | M9: =IF(COUNTIF(科学院!$B:$B,总表!$A9),INDEX(科学院!M:M,MATCH(总表!$A9,科学院!$B:$B,0)),0)+IF(COUNTIF(工程院!$B:$B,总表!$A9),INDEX(工程院!H:H,MATCH(总表!$A9,工程院!$B:$B,0)),0) -> 0 | N9: =IF(COUNTIF(科学院!$B:$B,总表!$A9),INDEX(科学院!N:N,MATCH(总表!$A9,科学院!$B:$B,0)),0)+IF(COUNTIF(工程院!$B:$B,总表!$A9),INDEX(工程院!I:I,MATCH(总表!$A9,工程院!$B:$B,0)),0) -> 0 | O9: =IF(COUNTIF(科学院!$B:$B,总表!$A9),INDEX(科学院!O:O,MATCH(总表!$A9,科学院!$B:$B,0)),0)+IF(COUNTIF(工程院!$B:$B,总表!$A9),INDEX(工程院!J:J,MATCH(总表!$A9,工程院!$B:$B,0)),0) -> 1 | P9: =IF(COUNTIF(科学院!$B:$B,总表!$A9),INDEX(科学院!P:P,MATCH(总表!$A9,科学院!$B:$B,0)),0)+IF(COUNTIF(工程院!$B:$B,总表!$A9),INDEX(工程院!K:K,MATCH(总表!$A9,工程院!$B:$B,0)),0) -> 1 | Q9: =IF(COUNTIF(科学院!$B:$B,总表!$A9),INDEX(科学院!Q:Q,MATCH(总表!$A9,科学院!$B:$B,0)),0)+IF(COUNTIF(工程院!$B:$B,总表!$A9),INDEX(工程院!L:L,MATCH(总表!$A9,工程院!$B:$B,0)),0) -> 1 | R9: =IF(COUNTIF(科学院!$B:$B,总表!$A9),INDEX(科学院!R:R,MATCH(总表!$A9,科学院!$B:$B,0)),0)+IF(COUNTIF(工程院!$B:$B,总表!$A9),INDEX(工程院!M:M,MATCH(总表!$A9,工程院!$B:$B,0)),0) -> 1 | S9: =IF(COUNTIF(科学院!$B:$B,总表!$A9),INDEX(科学院!S:S,MATCH(总表!$A9,科学院!$B:$B,0)),0)+IF(COUNTIF(工程院!$B:$B,总表!$A9),INDEX(工程院!N:N,MATCH(总表!$A9,工程院!$B:$B,0)),0) -> 3 | T9: =IF(COUNTIF(科学院!$B:$B,总表!$A9),INDEX(科学院!T:T,MATCH(总表!$A9,科学院!$B:$B,0)),0)+IF(COUNTIF(工程院!$B:$B,总表!$A9),INDEX(工程院!O:O,MATCH(总表!$A9,工程院!$B:$B,0)),0) -> 3 | U9: =IF(COUNTIF(科学院!$B:$B,总表!$A9),INDEX(科学院!U:U,MATCH(总表!$A9,科学院!$B:$B,0)),0)+IF(COUNTIF(工程院!$B:$B,总表!$A9),INDEX(工程院!P:P,MATCH(总表!$A9,工程院!$B:$B,0)),0) -> 3 | V9: =IF(COUNTIF(科学院!$B:$B,总表!$A9),INDEX(科学院!V:V,MATCH(总表!$A9,科学院!$B:$B,0)),0)+IF(COUNTIF(工程院!$B:$B,总表!$A9),INDEX(工程院!Q:Q,MATCH(总表!$A9,工程院!$B:$B,0)),0) -> 3
A10: 北方交通大学 | B10: =IF(COUNTIF(科学院!$B:$B,总表!$A10),INDEX(科学院!C:C,MATCH(总表!$A10,科学院!$B:$B,0)),0) -> 0 | C10: =IF(COUNTIF(科学院!$B:$B,总表!$A10),INDEX(科学院!D:D,MATCH(总表!$A10,科学院!$B:$B,0)),0) -> 0 | D10: =IF(COUNTIF(科学院!$B:$B,总表!$A10),INDEX(科学院!E:E,MATCH(总表!$A10,科学院!$B:$B,0)),0) -> 0 | E10: =IF(COUNTIF(科学院!$B:$B,总表!$A10),INDEX(科学院!F:F,MATCH(总表!$A10,科学院!$B:$B,0)),0) -> 0 | F10: =IF(COUNTIF(科学院!$B:$B,总表!$A10),INDEX(科学院!G:G,MATCH(总表!$A10,科学院!$B:$B,0)),0) -> 0 | G10: =IF(COUNTIF(科学院!$B:$B,总表!$A10),INDEX(科学院!H:H,MATCH(总表!$A10,科学院!$B:$B,0)),0) -> 0 | H10: =IF(COUNTIF(科学院!$B:$B,总表!$A10),INDEX(科学院!H:H,MATCH(总表!$A10,科学院!$B:$B,0)),0)+IF(COUNTIF(工程院!$B:$B,总表!$A10),INDEX(工程院!C:C,MATCH(总表!$A10,工程院!$B:$B,0)),0) -> 0 | I10: =IF(COUNTIF(科学院!$B:$B,总表!$A10),INDEX(科学院!I:I,MATCH(总表!$A10,科学院!$B:$B,0)),0)+IF(COUNTIF(工程院!$B:$B,总表!$A10),INDEX(工程院!D:D,MATCH(总表!$A10,工程院!$B:$B,0)),0) -> 0 | J10: =IF(COUNTIF(科学院!$B:$B,总表!$A10),INDEX(科学院!J:J,MATCH(总表!$A10,科学院!$B:$B,0)),0)+IF(COUNTIF(工程院!$B:$B,总表!$A10),INDEX(工程院!E:E,MATCH(总表!$A10,工程院!$B:$B,0)),0) -> 0 | K10: =IF(COUNTIF(科学院!$B:$B,总表!$A10),INDEX(科学院!K:K,MATCH(总表!$A10,科学院!$B:$B,0)),0)+IF(COUNTIF(工程院!$B:$B,总表!$A10),INDEX(工程院!F:F,MATCH(总表!$A10,工程院!$B:$B,0)),0) -> 0 | L10: =IF(COUNTIF(科学院!$B:$B,总表!$A10),INDEX(科学院!L:L,MATCH(总表!$A10,科学院!$B:$B,0)),0)+IF(COUNTIF(工程院!$B:$B,总表!$A10),INDEX(工程院!G:G,MATCH(总表!$A10,工程院!$B:$B,0)),0) -> 1 | M10: =IF(COUNTIF(科学院!$B:$B,总表!$A10),INDEX(科学院!M:M,MATCH(总表!$A10,科学院!$B:$B,0)),0)+IF(COUNTIF(工程院!$B:$B,总表!$A10),INDEX(工程院!H:H,MATCH(总表!$A10,工程院!$B:$B,0)),0) -> 1 | N10: =IF(COUNTIF(科学院!$B:$B,总表!$A10),INDEX(科学院!N:N,MATCH(总表!$A10,科学院!$B:$B,0)),0)+IF(COUNTIF(工程院!$B:$B,总表!$A10),INDEX(工程院!I:I,MATCH(总表!$A10,工程院!$B:$B,0)),0) -> 1 | O10: =IF(COUNTIF(科学院!$B:$B,总表!$A10),INDEX(科学院!O:O,MATCH(总表!$A10,科学院!$B:$B,0)),0)+IF(COUNTIF(工程院!$B:$B,总表!$A10),INDEX(工程院!J:J,MATCH(总表!$A10,工程院!$B:$B,0)),0) -> 1 | P10: =IF(COUNTIF(科学院!$B:$B,总表!$A10),INDEX(科学院!P:P,MATCH(总表!$A10,科学院!$B:$B,0)),0)+IF(COUNTIF(工程院!$B:$B,总表!$A10),INDEX(工程院!K:K,MATCH(总表!$A10,工程院!$B:$B,0)),0) -> 1 | Q10: =IF(COUNTIF(科学院!$B:$B,总表!$A10),INDEX(科学院!Q:Q,MATCH(总表!$A10,科学院!$B:$B,0)),0)+IF(COUNTIF(工程院!$B:$B,总表!$A10),INDEX(工程院!L:L,MATCH(总表!$A10,工程院!$B:$B,0)),0) -> 1 | R10: =IF(COUNTIF(科学院!$B:$B,总表!$A10),INDEX(科学院!R:R,MATCH(总表!$A10,科学院!$B:$B,0)),0)+IF(COUNTIF(工程院!$B:$B,总表!$A10),INDEX(工程院!M:M,MATCH(总表!$A10,工程院!$B:$B,0)),0) -> 1 | S10: =IF(COUNTIF(科学院!$B:$B,总表!$A10),INDEX(科学院!S:S,MATCH(总表!$A10,科学院!$B:$B,0)),0)+IF(COUNTIF(工程院!$B:$B,总表!$A10),INDEX(工程院!N:N,MATCH(总表!$A10,工程院!$B:$B,0)),0) -> 1 | T10: =IF(COUNTIF(科学院!$B:$B,总表!$A10),INDEX(科学院!T:T,MATCH(总表!$A10,科学院!$B:$B,0)),0)+IF(COUNTIF(工程院!$B:$B,总表!$A10),INDEX(工程院!O:O,MATCH(总表!$A10,工程院!$B:$B,0)),0) -> 1 | U10: =IF(COUNTIF(科学院!$B:$B,总表!$A10),INDEX(科学院!U:U,MATCH(总表!$A10,科学院!$B:$B,0)),0)+IF(COUNTIF(工程院!$B:$B,总表!$A10),INDEX(工程院!P:P,MATCH(总表!$A10,工程院!$B:$B,0)),0) -> 2 | V10: =IF(COUNTIF(科学院!$B:$B,总表!$A10),INDEX(科学院!V:V,MATCH(总表!$A10,科学院!$B:$B,0)),0)+IF(COUNTIF(工程院!$B:$B,总表!$A10),INDEX(工程院!Q:Q,MATCH(总表!$A10,工程院!$B:$B,0)),0) -> 2
A11: 北京大学 | B11: =IF(COUNTIF(科学院!$B:$B,总表!$A11),INDEX(科学院!C:C,MATCH(总表!$A11,科学院!$B:$B,0)),0) -> 3 | C11: =IF(COUNTIF(科学院!$B:$B,总表!$A11),INDEX(科学院!D:D,MATCH(总表!$A11,科学院!$B:$B,0)),0) -> 19 | D11: =IF(COUNTIF(科学院!$B:$B,总表!$A11),INDEX(科学院!E:E,MATCH(总表!$A11,科学院!$B:$B,0)),0) -> 22 | E11: =IF(COUNTIF(科学院!$B:$B,总表!$A11),INDEX(科学院!F:F,MATCH(总表!$A11,科学院!$B:$B,0)),0) -> 50 | F11: =IF(COUNTIF(科学院!$B:$B,总表!$A11),INDEX(科学院!G:G,MATCH(总表!$A11,科学院!$B:$B,0)),0) -> 72 | G11: =IF(COUNTIF(科学院!$B:$B,总表!$A11),INDEX(科学院!H:H,MATCH(总表!$A11,科学院!$B:$B,0)),0) -> 81 | H11: =IF(COUNTIF(科学院!$B:$B,总表!$A11),INDEX(科学院!H:H,MATCH(总表!$A11,科学院!$B:$B,0)),0)+IF(COUNTIF(工程院!$B:$B,总表!$A11),INDEX(工程院!C:C,MATCH(总表!$A11,工程院!$B:$B,0)),0) -> 89 | I11: =IF(COUNTIF(科学院!$B:$B,总表!$A11),INDEX(科学院!I:I,MATCH(总表!$A11,科学院!$B:$B,0)),0)+IF(COUNTIF(工程院!$B:$B,总表!$A11),INDEX(工程院!D:D,MATCH(总表!$A11,工程院!$B:$B,0)),0) -> 110 | J11: =IF(COUNTIF(科学院!$B:$B,总表!$A11),INDEX(科学院!J:J,MATCH(总表!$A11,科学院!$B:$B,0)),0)+IF(COUNTIF(工程院!$B:$B,总表!$A11),INDEX(工程院!E:E,MATCH(总表!$A11,工程院!$B:$B,0)),0) -> 125 | K11: =IF(COUNTIF(科学院!$B:$B,总表!$A11),INDEX(科学院!K:K,MATCH(总表!$A11,科学院!$B:$B,0)),0)+IF(COUNTIF(工程院!$B:$B,总表!$A11),INDEX(工程院!F:F,MATCH(总表!$A11,工程院!$B:$B,0)),0) -> 139 | L11: =IF(COUNTIF(科学院!$B:$B,总表!$A11),INDEX(科学院!L:L,MATCH(总表!$A11,科学院!$B:$B,0)),0)+IF(COUNTIF(工程院!$B:$B,总表!$A11),INDEX(工程院!G:G,MATCH(总表!$A11,工程院!$B:$B,0)),0) -> 151 | M11: =IF(COUNTIF(科学院!$B:$B,总表!$A11),INDEX(科学院!M:M,MATCH(总表!$A11,科学院!$B:$B,0)),0)+IF(COUNTIF(工程院!$B:$B,总表!$A11),INDEX(工程院!H:H,MATCH(总表!$A11,工程院!$B:$B,0)),0) -> 158 | N11: =IF(COUNTIF(科学院!$B:$B,总表!$A11),INDEX(科学院!N:N,MATCH(总表!$A11,科学院!$B:$B,0)),0)+IF(COUNTIF(工程院!$B:$B,总表!$A11),INDEX(工程院!I:I,MATCH(总表!$A11,工程院!$B:$B,0)),0) -> 164 | O11: =IF(COUNTIF(科学院!$B:$B,总表!$A11),INDEX(科学院!O:O,MATCH(总表!$A11,科学院!$B:$B,0)),0)+IF(COUNTIF(工程院!$B:$B,总表!$A11),INDEX(工程院!J:J,MATCH(总表!$A11,工程院!$B:$B,0)),0) -> 168 | P11: =IF(COUNTIF(科学院!$B:$B,总表!$A11),INDEX(科学院!P:P,MATCH(总表!$A11,科学院!$B:$B,0)),0)+IF(COUNTIF(工程院!$B:$B,总表!$A11),INDEX(工程院!K:K,MATCH(总表!$A11,工程院!$B:$B,0)),0) -> 170 | Q11: =IF(COUNTIF(科学院!$B:$B,总表!$A11),INDEX(科学院!Q:Q,MATCH(总表!$A11,科学院!$B:$B,0)),0)+IF(COUNTIF(工程院!$B:$B,总表!$A11),INDEX(工程院!L:L,MATCH(总表!$A11,工程院!$B:$B,0)),0) -> 177 | R11: =IF(COUNTIF(科学院!$B:$B,总表!$A11),INDEX(科学院!R:R,MATCH(总表!$A11,科学院!$B:$B,0)),0)+IF(COUNTIF(工程院!$B:$B,总表!$A11),INDEX(工程院!M:M,MATCH(总表!$A11,工程院!$B:$B,0)),0) -> 186 | S11: =IF(COUNTIF(科学院!$B:$B,总表!$A11),INDEX(科学院!S:S,MATCH(总表!$A11,科学院!$B:$B,0)),0)+IF(COUNTIF(工程院!$B:$B,总表!$A11),INDEX(工程院!N:N,MATCH(总表!$A11,工程院!$B:$B,0)),0) -> 189 | T11: =IF(COUNTIF(科学院!$B:$B,总表!$A11),INDEX(科学院!T:T,MATCH(总表!$A11,科学院!$B:$B,0)),0)+IF(COUNTIF(工程院!$B:$B,总表!$A11),INDEX(工程院!O:O,MATCH(总表!$A11,工程院!$B:$B,0)),0) -> 196 | U11: =IF(COUNTIF(科学院!$B:$B,总表!$A11),INDEX(科学院!U:U,MATCH(总表!$A11,科学院!$B:$B,0)),0)+IF(COUNTIF(工程院!$B:$B,总表!$A11),INDEX(工程院!P:P,MATCH(总表!$A11,工程院!$B:$B,0)),0) -> 199 | V11: =IF(COUNTIF(科学院!$B:$B,总表!$A11),INDEX(科学院!V:V,MATCH(总表!$A11,科学院!$B:$B,0)),0)+IF(COUNTIF(工程院!$B:$B,总表!$A11),INDEX(工程院!Q:Q,MATCH(总表!$A11,工程院!$B:$B,0)),0) -> 207
A12: 北京地质学院 | B12: =IF(COUNTIF(科学院!$B:$B,总表!$A12),INDEX(科学院!C:C,MATCH(总表!$A12,科学院!$B:$B,0)),0) -> 0 | C12: =IF(COUNTIF(科学院!$B:$B,总表!$A12),INDEX(科学院!D:D,MATCH(总表!$A12,科学院!$B:$B,0)),0) -> 0 | D12: =IF(COUNTIF(科学院!$B:$B,总表!$A12),INDEX(科学院!E:E,MATCH(总表!$A12,科学院!$B:$B,0)),0) -> 0 | E12: =IF(COUNTIF(科学院!$B:$B,总表!$A12),INDEX(科学院!F:F,MATCH(总表!$A12,科学院!$B:$B,0)),0) -> 0 | F12: =IF(COUNTIF(科学院!$B:$B,总表!$A12),INDEX(科学院!G:G,MATCH(总表!$A12,科学院!$B:$B,0)),0) -> 6 | G12: =IF(COUNTIF(科学院!$B:$B,总表!$A12),INDEX(科学院!H:H,MATCH(总表!$A12,科学院!$B:$B,0)),0) -> 9 | H12: =IF(COUNTIF(科学院!$B:$B,总表!$A12),INDEX(科学院!H:H,MATCH(总表!$A12,科学院!$B:$B,0)),0)+IF(COUNTIF(工程院!$B:$B,总表!$A12),INDEX(工程院!C:C,MATCH(总表!$A12,工程院!$B:$B,0)),0) -> 9 | I12: =IF(COUNTIF(科学院!$B:$B,总表!$A12),INDEX(科学院!I:I,MATCH(总表!$A12,科学院!$B:$B,0)),0)+IF(COUNTIF(工程院!$B:$B,总表!$A12),INDEX(工程院!D:D,MATCH(总表!$A12,工程院!$B:$B,0)),0) -> 12 | J12: =IF(COUNTIF(科学院!$B:$B,总表!$A12),INDEX(科学院!J:J,MATCH(总表!$A12,科学院!$B:$B,0)),0)+IF(COUNTIF(工程院!$B:$B,总表!$A12),INDEX(工程院!E:E,MATCH(总表!$A12,工程院!$B:$B,0)),0) -> 15 | K12: =IF(COUNTIF(科学院!$B:$B,总表!$A12),INDEX(科学院!K:K,MATCH(总表!$A12,科学院!$B:$B,0)),0)+IF(COUNTIF(工程院!$B:$B,总表!$A12),INDEX(工程院!F:F,MATCH(总表!$A12,工程院!$B:$B,0)),0) -> 17 | L12: =IF(COUNTIF(科学院!$B:$B,总表!$A12),INDEX(科学院!L:L,MATCH(总表!$A12,科学院!$B:$B,0)),0)+IF(COUNTIF(工程院!$B:$B,总表!$A12),INDEX(工程院!G:G,MATCH(总表!$A12,工程院!$B:$B,0)),0) -> 18 | M12: =IF(COUNTIF(科学院!$B:$B,总表!$A12),INDEX(科学院!M:M,MATCH(总表!$A12,科学院!$B:$B,0)),0)+IF(COUNTIF(工程院!$B:$B,总表!$A12),INDEX(工程院!H:H,MATCH(总表!$A12,工程院!$B:$B,0)),0) -> 19 | N12: =IF(COUNTIF(科学院!$B:$B,总表!$A12),INDEX(科学院!N:N,MATCH(总表!$A12,科学院!$B:$B,0)),0)+IF(COUNTIF(工程院!$B:$B,总表!$A12),INDEX(工程院!I:I,MATCH(总表!$A12,工程院!$B:$B,0)),0) -> 21 | O12: =IF(COUNTIF(科学院!$B:$B,总表!$A12),INDEX(科学院!O:O,MATCH(总表!$A12,科学院!$B:$B,0)),0)+IF(COUNTIF(工程院!$B:$B,总表!$A12),INDEX(工程院!J:J,MATCH(总表!$A12,工程院!$B:$B,0)),0) -> 21 | P12: =IF(COUNTIF(科学院!$B:$B,总表!$A12),INDEX(科学院!P:P,MATCH(总表!$A12,科学院!$B:$B,0)),0)+IF(COUNTIF(工程院!$B:$B,总表!$A12),INDEX(工程院!K:K,MATCH(总表!$A12,工程院!$B:$B,0)),0) -> 22 | Q12: =IF(COUNTIF(科学院!$B:$B,总表!$A12),INDEX(科学院!Q:Q,MATCH(总表!$A12,科学院!$B:$B,0)),0)+IF(COUNTIF(工程院!$B:$B,总表!$A12),INDEX(工程院!L:L,MATCH(总表!$A12,工程院!$B:$B,0)),0) -> 22 | R12: =IF(COUNTIF(科学院!$B:$B,总表!$A12),INDEX(科学院!R:R,MATCH(总表!$A12,科学院!$B:$B,0)),0)+IF(COUNTIF(工程院!$B:$B,总表!$A12),INDEX(工程院!M:M,MATCH(总表!$A12,工程院!$B:$B,0)),0) -> 22 | S12: =IF(COUNTIF(科学院!$B:$B,总表!$A12),INDEX(科学院!S:S,MATCH(总表!$A12,科学院!$B:$B,0)),0)+IF(COUNTIF(工程院!$B:$B,总表!$A12),INDEX(工程院!N:N,MATCH(总表!$A12,工程院!$B:$B,0)),0) -> 22 | T12: =IF(COUNTIF(科学院!$B:$B,总表!$A12),INDEX(科学院!T:T,MATCH(总表!$A12,科学院!$B:$B,0)),0)+IF(COUNTIF(工程院!$B:$B,总表!$A12),INDEX(工程院!O:O,MATCH(总表!$A12,工程院!$B:$B,0)),0) -> 22 | U12: =IF(COUNTIF(科学院!$B:$B,总表!$A12),INDEX(科学院!U:U,MATCH(总表!$A12,科学院!$B:$B,0)),0)+IF(COUNTIF(工程院!$B:$B,总表!$A12),INDEX(工程院!P:P,MATCH(总表!$A12,工程院!$B:$B,0)),0) -> 22 | V12: =IF(COUNTIF(科学院!$B:$B,总表!$A12),INDEX(科学院!V:V,MATCH(总表!$A12,科学院!$B:$B,0)),0)+IF(COUNTIF(工程院!$B:$B,总表!$A12),INDEX(工程院!Q:Q,MATCH(总表!$A12,工程院!$B:$B,0)),0) -> 22
A13: 北京辅仁大学 | B13: =IF(COUNTIF(科学院!$B:$B,总表!$A13),INDEX(科学院!C:C,MATCH(总表!$A13,科学院!$B:$B,0)),0) -> 0 | C13: =IF(COUNTIF(科学院!$B:$B,总表!$A13),INDEX(科学院!D:D,MATCH(总表!$A13,科学院!$B:$B,0)),0) -> 0 | D13: =IF(COUNTIF(科学院!$B:$B,总表!$A13),INDEX(科学院!E:E,MATCH(总表!$A13,科学院!$B:$B,0)),0) -> 0 | E13: =IF(COUNTIF(科学院!$B:$B,总表!$A13),INDEX(科学院!F:F,MATCH(总表!$A13,科学院!$B:$B,0)),0) -> 0 | F13: =IF(COUNTIF(科学院!$B:$B,总表!$A13),INDEX(科学院!G:G,MATCH(总表!$A13,科学院!$B:$B,0)),0) -> 0 | G13: =IF(COUNTIF(科学院!$B:$B,总表!$A13),INDEX(科学院!H:H,MATCH(总表!$A13,科学院!$B:$B,0)),0) -> 0 | H13: =IF(COUNTIF(科学院!$B:$B,总表!$A13),INDEX(科学院!H:H,MATCH(总表!$A13,科学院!$B:$B,0)),0)+IF(COUNTIF(工程院!$B:$B,总表!$A13),INDEX(工程院!C:C,MATCH(总表!$A13,工程院!$B:$B,0)),0) -> 0 | I13: =IF(COUNTIF(科学院!$B:$B,总表!$A13),INDEX(科学院!I:I,MATCH(总表!$A13,科学院!$B:$B,0)),0)+IF(COUNTIF(工程院!$B:$B,总表!$A13),INDEX(工程院!D:D,MATCH(总表!$A13,工程院!$B:$B,0)),0) -> 1 | J13: =IF(COUNTIF(科学院!$B:$B,总表!$A13),INDEX(科学院!J:J,MATCH(总表!$A13,科学院!$B:$B,0)),0)+IF(COUNTIF(工程院!$B:$B,总表!$A13),INDEX(工程院!E:E,MATCH(总表!$A13,工程院!$B:$B,0)),0) -> 1 | K13: =IF(COUNTIF(科学院!$B:$B,总表!$A13),INDEX(科学院!K:K,MATCH(总表!$A13,科学院!$B:$B,0)),0)+IF(COUNTIF(工程院!$B:$B,总表!$A13),INDEX(工程院!F:F,MATCH(总表!$A13,工程院!$B:$B,0)),0) -> 2 | L13: =IF(COUNTIF(科学院!$B:$B,总表!$A13),INDEX(科学院!L:L,MATCH(总表!$A13,科学院!$B:$B,0)),0)+IF(COUNTIF(工程院!$B:$B,总表!$A13),INDEX(工程院!G:G,MATCH(总表!$A13,工程院!$B:$B,0)),0) -> 2 | M13: =IF(COUNTIF(科学院!$B:$B,总表!$A13),INDEX(科学院!M:M,MATCH(总表!$A13,科学院!$B:$B,0)),0)+IF(COUNTIF(工程院!$B:$B,总表!$A13),INDEX(工程院!H:H,MATCH(总表!$A13,工程院!$B:$B,0)),0) -> 2 | N13: =IF(COUNTIF(科学院!$B:$B,总表!$A13),INDEX(科学院!N:N,MATCH(总表!$A13,科学院!$B:$B,0)),0)+IF(COUNTIF(工程院!$B:$B,总表!$A13),INDEX(工程院!I:I,MATCH(总表!$A13,工程院!$B:$B,0)),0) -> 2 | O13: =IF(COUNTIF(科学院!$B:$B,总表!$A13),INDEX(科学院!O:O,MATCH(总表!$A13,科学院!$B:$B,0)),0)+IF(COUNTIF(工程院!$B:$B,总表!$A13),INDEX(工程院!J:J,MATCH(总表!$A13,工程院!$B:$B,0)),0) -> 2 | P13: =IF(COUNTIF(科学院!$B:$B,总表!$A13),INDEX(科学院!P:P,MATCH(总表!$A13,科学院!$B:$B,0)),0)+IF(COUNTIF(工程院!$B:$B,总表!$A13),INDEX(工程院!K:K,MATCH(总表!$A13,工程院!$B:$B,0)),0) -> 2 | Q13: =IF(COUNTIF(科学院!$B:$B,总表!$A13),INDEX(科学院!Q:Q,MATCH(总表!$A13,科学院!$B:$B,0)),0)+IF(COUNTIF(工程院!$B:$B,总表!$A13),INDEX(工程院!L:L,MATCH(总表!$A13,工程院!$B:$B,0)),0) -> 2 | R13: =IF(COUNTIF(科学院!$B:$B,总表!$A13),INDEX(科学院!R:R,MATCH(总表!$A13,科学院!$B:$B,0)),0)+IF(COUNTIF(工程院!$B:$B,总表!$A13),INDEX(工程院!M:M,MATCH(总表!$A13,工程院!$B:$B,0)),0) -> 2 | S13: =IF(COUNTIF(科学院!$B:$B,总表!$A13),INDEX(科学院!S:S,MATCH(总表!$A13,科学院!$B:$B,0)),0)+IF(COUNTIF(工程院!$B:$B,总表!$A13),INDEX(工程院!N:N,MATCH(总表!$A13,工程院!$B:$B,0)),0) -> 2 | T13: =IF(COUNTIF(科学院!$B:$B,总表!$A13),INDEX(科学院!T:T,MATCH(总表!$A13,科学院!$B:$B,0)),0)+IF(COUNTIF(工程院!$B:$B,总表!$A13),INDEX(工程院!O:O,MATCH(总表!$A13,工程院!$B:$B,0)),0) -> 2 | U13: =IF(COUNTIF(科学院!$B:$B,总表!$A13),INDEX(科学院!U:U,MATCH(总表!$A13,科学院!$B:$B,0)),0)+IF(COUNTIF(工程院!$B:$B,总表!$A13),INDEX(工程院!P:P,MATCH(总表!$A13,工程院!$B:$B,0)),0) -> 2 | V13: =IF(COUNTIF(科学院!$B:$B,总表!$A13),INDEX(科学院!V:V,MATCH(总表!$A13,科学院!$B:$B,0)),0)+IF(COUNTIF(工程院!$B:$B,总表!$A13),INDEX(工程院!Q:Q,MATCH(总表!$A13,工程院!$B:$B,0)),0) -> 2
... A610: 中正医学院 | B610: =IF(COUNTIF(科学院!$B:$B,总表!$A610),INDEX(科学院!C:C,MATCH(总表!$A610,科学院!$B:$B,0)),0) -> 0 | C610: =IF(COUNTIF(科学院!$B:$B,总表!$A610),INDEX(科学院!D:D,MATCH(总表!$A610,科学院!$B:$B,0)),0) -> 0 | D610: =IF(COUNTIF(科学院!$B:$B,总表!$A610),INDEX(科学院!E:E,MATCH(总表!$A610,科学院!$B:$B,0)),0) -> 0 | E610: =IF(COUNTIF(科学院!$B:$B,总表!$A610),INDEX(科学院!F:F,MATCH(总表!$A610,科学院!$B:$B,0)),0) -> 0 | F610: =IF(COUNTIF(科学院!$B:$B,总表!$A610),INDEX(科学院!G:G,MATCH(总表!$A610,科学院!$B:$B,0)),0) -> 0 | G610: =IF(COUNTIF(科学院!$B:$B,总表!$A610),INDEX(科学院!H:H,MATCH(总表!$A610,科学院!$B:$B,0)),0) -> 0 | H610: =IF(COUNTIF(科学院!$B:$B,总表!$A610),INDEX(科学院!H:H,MATCH(总表!$A610,科学院!$B:$B,0)),0)+IF(COUNTIF(工程院!$B:$B,总表!$A610),INDEX(工程院!C:C,MATCH(总表!$A610,工程院!$B:$B,0)),0) -> 1 | I610: =IF(COUNTIF(科学院!$B:$B,总表!$A610),INDEX(科学院!I:I,MATCH(总表!$A610,科学院!$B:$B,0)),0)+IF(COUNTIF(工程院!$B:$B,总表!$A610),INDEX(工程院!D:D,MATCH(总表!$A610,工程院!$B:$B,0)),0) -> 1 | J610: =IF(COUNTIF(科学院!$B:$B,总表!$A610),INDEX(科学院!J:J,MATCH(总表!$A610,科学院!$B:$B,0)),0)+IF(COUNTIF(工程院!$B:$B,总表!$A610),INDEX(工程院!E:E,MATCH(总表!$A610,工程院!$B:$B,0)),0) -> 2 | K610: =IF(COUNTIF(科学院!$B:$B,总表!$A610),INDEX(科学院!K:K,MATCH(总表!$A610,科学院!$B:$B,0)),0)+IF(COUNTIF(工程院!$B:$B,总表!$A610),INDEX(工程院!F:F,MATCH(总表!$A610,工程院!$B:$B,0)),0) -> 4 | L610: =IF(COUNTIF(科学院!$B:$B,总表!$A610),INDEX(科学院!L:L,MATCH(总表!$A610,科学院!$B:$B,0)),0)+IF(COUNTIF(工程院!$B:$B,总表!$A610),INDEX(工程院!G:G,MATCH(总表!$A610,工程院!$B:$B,0)),0) -> 5 | M610: =IF(COUNTIF(科学院!$B:$B,总表!$A610),INDEX(科学院!M:M,MATCH(总表!$A610,科学院!$B:$B,0)),0)+IF(COUNTIF(工程院!$B:$B,总表!$A610),INDEX(工程院!H:H,MATCH(总表!$A610,工程院!$B:$B,0)),0) -> 5 | N610: =IF(COUNTIF(科学院!$B:$B,总表!$A610),INDEX(科学院!N:N,MATCH(总表!$A610,科学院!$B:$B,0)),0)+IF(COUNTIF(工程院!$B:$B,总表!$A610),INDEX(工程院!I:I,MATCH(总表!$A610,工程院!$B:$B,0)),0) -> 5 | O610: =IF(COUNTIF(科学院!$B:$B,总表!$A610),INDEX(科学院!O:O,MATCH(总表!$A610,科学院!$B:$B,0)),0)+IF(COUNTIF(工程院!$B:$B,总表!$A610),INDEX(工程院!J:J,MATCH(总表!$A610,工程院!$B:$B,0)),0) -> 5 | P610: =IF(COUNTIF(科学院!$B:$B,总表!$A610),INDEX(科学院!P:P,MATCH(总表!$A610,科学院!$B:$B,0)),0)+IF(COUNTIF(工程院!$B:$B,总表!$A610),INDEX(工程院!K:K,MATCH(总表!$A610,工程院!$B:$B,0)),0) -> 5 | Q610: =IF(COUNTIF(科学院!$B:$B,总表!$A610),INDEX(科学院!Q:Q,MATCH(总表!$A610,科学院!$B:$B,0)),0)+IF(COUNTIF(工程院!$B:$B,总表!$A610),INDEX(工程院!L:L,MATCH(总表!$A610,工程院!$B:$B,0)),0) -> 5 | R610: =IF(COUNTIF(科学院!$B:$B,总表!$A610),INDEX(科学院!R:R,MATCH(总表!$A610,科学院!$B:$B,0)),0)+IF(COUNTIF(工程院!$B:$B,总表!$A610),INDEX(工程院!M:M,MATCH(总表!$A610,工程院!$B:$B,0)),0) -> 5 | S610: =IF(COUNTIF(科学院!$B:$B,总表!$A610),INDEX(科学院!S:S,MATCH(总表!$A610,科学院!$B:$B,0)),0)+IF(COUNTIF(工程院!$B:$B,总表!$A610),INDEX(工程院!N:N,MATCH(总表!$A610,工程院!$B:$B,0)),0) -> 5 | T610: =IF(COUNTIF(科学院!$B:$B,总表!$A610),INDEX(科学院!T:T,MATCH(总表!$A610,科学院!$B:$B,0)),0)+IF(COUNTIF(工程院!$B:$B,总表!$A610),INDEX(工程院!O:O,MATCH(总表!$A610,工程院!$B:$B,0)),0) -> 5 | U610: =IF(COUNTIF(科学院!$B:$B,总表!$A610),INDEX(科学院!U:U,MATCH(总表!$A610,科学院!$B:$B,0)),0)+IF(COUNTIF(工程院!$B:$B,总表!$A610),INDEX(工程院!P:P,MATCH(总表!$A610,工程院!$B:$B,0)),0) -> 5 | V610: =IF(COUNTIF(科学院!$B:$B,总表!$A610),INDEX(科学院!V:V,MATCH(总表!$A610,科学院!$B:$B,0)),0)+IF(COUNTIF(工程院!$B:$B,总表!$A610),INDEX(工程院!Q:Q,MATCH(总表!$A610,工程院!$B:$B,0)),0) -> 5
